Workbook

Sheet Dashboard
B1: Belanjawan Kelab Guru
B2: ="Dikemas kini "&TEXT(TODAY(),"d mmm yyyy")&" · data daripada tab Transaksi"
B4: BAKI SEMASA | E4: JUMLAH MASUK | H4: JUMLAH KELUAR | K4: YURAN BELUM BAYAR
B5: =SUM(Transaksi!$G$2:$I$2001)-SUM(Transaksi!$J$2:$J$2001) | E5: =SUM(Transaksi!$G$2:$I$2001) | H5: =SUM(Transaksi!$J$2:$J$2001) | K5: =SUM(Yuran!$X$5:$X$24)
K6: anggaran, ikut jadual Yuran
B8: Lihat bulan | C8: =DATE(YEAR(TODAY()),MONTH(TODAY()),1) | E8: ◂ pilih bulan daripada senarai
B10: MASUK | D10: KELUAR | F10: BERSIH | H10: BIL. REKOD | J10: KELAB DIBAYAR | L10: BELANJA TERBESAR
B11: =SUMIFS(Transaksi!$G$2:$G$2001,Transaksi!$A$2:$A$2001,">="&$C$8,Transaksi!$A$2:$A$2001,"<"&EDATE($C$8,1))+SUMIFS(Transaksi!$H$2:$H$2001,Transaksi!$A$2:$A$2001,">="&$C$8,Transaksi!$A$2:$A$2001,"<"&EDATE($C$8,1))+SUMIFS(Transaksi!$I$2:$I$2001,Transaksi!$A$2:$A$2001,">="&$C$8,Transaksi!$A$2:$A$2001,"<"&EDATE($C$8,1)) | D11: =SUMIFS(Transaksi!$J$2:$J$2001,Transaksi!$A$2:$A$2001,">="&$C$8,Transaksi!$A$2:$A$2001,"<"&EDATE($C$8,1)) | F11: =SUMIFS(Transaksi!$G$2:$G$2001,Transaksi!$A$2:$A$2001,">="&$C$8,Transaksi!$A$2:$A$2001,"<"&EDATE($C$8,1))+SUMIFS(Transaksi!$H$2:$H$2001,Transaksi!$A$2:$A$2001,">="&$C$8,Transaksi!$A$2:$A$2001,"<"&EDATE($C$8,1))+SUMIFS(Transaksi!$I$2:$I$2001,Transaksi!$A$2:$A$2001,">="&$C$8,Transaksi!$A$2:$A$2001,"<"&EDATE($C$8,1))-(SUMIFS(Transaksi!$J$2:$J$2001,Transaksi!$A$2:$A$2001,">="&$C$8,Transaksi!$A$2:$A$2001,"<"&EDATE($C$8,1))) | H11: =COUNTIFS(Transaksi!$A$2:$A$2001,">="&$C$8,Transaksi!$A$2:$A$2001,"<"&EDATE($C$8,1)) | J11: =COUNTIF(INDEX(Yuran!$B$29:$T$48,0,MATCH($C$8,Yuran!$B$28:$T$28,0)),"✓")&" / "&(COUNTIF(INDEX(Yuran!$B$29:$T$48,0,MATCH($C$8,Yuran!$B$28:$T$28,0)),"✓")+COUNTIF(INDEX(Yuran!$B$29:$T$48,0,MATCH($C$8,Yuran!$B$28:$T$28,0)),"✗")+COUNTIF(INDEX(Yuran!$B$29:$T$48,0,MATCH($C$8,Yuran!$B$28:$T$28,0)),"½"))&" ahli" | L11: =SUMPRODUCT(MAX((Transaksi!$J$2:$J$2001)*(Transaksi!$A$2:$A$2001>=$C$8)*(Transaksi!$A$2:$A$2001<EDATE($C$8,1))))
L12: =IF(SUMPRODUCT(MAX((Transaksi!$J$2:$J$2001)*(Transaksi!$A$2:$A$2001>=$C$8)*(Transaksi!$A$2:$A$2001<EDATE($C$8,1))))=0,"-",INDEX(Transaksi!$B$1:$B$2001,SUMPRODUCT(MAX((Transaksi!$J$2:$J$2001=SUMPRODUCT(MAX((Transaksi!$J$2:$J$2001)*(Transaksi!$A$2:$A$2001>=$C$8)*(Transaksi!$A$2:$A$2001<EDATE($C$8,1)))))*(Transaksi!$A$2:$A$2001>=$C$8)*(Transaksi!$A$2:$A$2001<EDATE($C$8,1))*ROW(Transaksi!$J$2:$J$2001)))))
B14: Graf
B49: Pergerakan bulanan
B51: Bulan | C51: Masuk | D51: Keluar | E51: Bersih | F51: Baki akhir | G51: Kelab | H51: Lawatan | I51: Lain
B52: =EDATE(Tetapan!$B$28,0) | C52: =SUMIFS(Transaksi!$G$2:$G$2001,Transaksi!$A$2:$A$2001,">="&$B52,Transaksi!$A$2:$A$2001,"<"&EDATE($B52,1))+SUMIFS(Transaksi!$H$2:$H$2001,Transaksi!$A$2:$A$2001,">="&$B52,Transaksi!$A$2:$A$2001,"<"&EDATE($B52,1))+SUMIFS(Transaksi!$I$2:$I$2001,Transaksi!$A$2:$A$2001,">="&$B52,Transaksi!$A$2:$A$2001,"<"&EDATE($B52,1)) | D52: =SUMIFS(Transaksi!$J$2:$J$2001,Transaksi!$A$2:$A$2001,">="&$B52,Transaksi!$A$2:$A$2001,"<"&EDATE($B52,1)) | E52: =C52-D52 | F52: =SUM(E$52:E52) | G52: =SUMIFS(Transaksi!$G$2:$G$2001,Transaksi!$A$2:$A$2001,">="&$B52,Transaksi!$A$2:$A$2001,"<"&EDATE($B52,1)) | H52: =SUMIFS(Transaksi!$H$2:$H$2001,Transaksi!$A$2:$A$2001,">="&$B52,Transaksi!$A$2:$A$2001,"<"&EDATE($B52,1)) | I52: =SUMIFS(Transaksi!$I$2:$I$2001,Transaksi!$A$2:$A$2001,">="&$B52,Transaksi!$A$2:$A$2001,"<"&EDATE($B52,1))
B53: =EDATE(Tetapan!$B$28,1) | C53: =SUMIFS(Transaksi!$G$2:$G$2001,Transaksi!$A$2:$A$2001,">="&$B53,Transaksi!$A$2:$A$2001,"<"&EDATE($B53,1))+SUMIFS(Transaksi!$H$2:$H$2001,Transaksi!$A$2:$A$2001,">="&$B53,Transaksi!$A$2:$A$2001,"<"&EDATE($B53,1))+SUMIFS(Transaksi!$I$2:$I$2001,Transaksi!$A$2:$A$2001,">="&$B53,Transaksi!$A$2:$A$2001,"<"&EDATE($B53,1)) | D53: =SUMIFS(Transaksi!$J$2:$J$2001,Transaksi!$A$2:$A$2001,">="&$B53,Transaksi!$A$2:$A$2001,"<"&EDATE($B53,1)) | E53: =C53-D53 | F53: =SUM(E$52:E53) | G53: =SUMIFS(Transaksi!$G$2:$G$2001,Transaksi!$A$2:$A$2001,">="&$B53,Transaksi!$A$2:$A$2001,"<"&EDATE($B53,1)) | H53: =SUMIFS(Transaksi!$H$2:$H$2001,Transaksi!$A$2:$A$2001,">="&$B53,Transaksi!$A$2:$A$2001,"<"&EDATE($B53,1)) | I53: =SUMIFS(Transaksi!$I$2:$I$2001,Transaksi!$A$2:$A$2001,">="&$B53,Transaksi!$A$2:$A$2001,"<"&EDATE($B53,1))
B54: =EDATE(Tetapan!$B$28,2) | C54: =SUMIFS(Transaksi!$G$2:$G$2001,Transaksi!$A$2:$A$2001,">="&$B54,Transaksi!$A$2:$A$2001,"<"&EDATE($B54,1))+SUMIFS(Transaksi!$H$2:$H$2001,Transaksi!$A$2:$A$2001,">="&$B54,Transaksi!$A$2:$A$2001,"<"&EDATE($B54,1))+SUMIFS(Transaksi!$I$2:$I$2001,Transaksi!$A$2:$A$2001,">="&$B54,Transaksi!$A$2:$A$2001,"<"&EDATE($B54,1)) | D54: =SUMIFS(Transaksi!$J$2:$J$2001,Transaksi!$A$2:$A$2001,">="&$B54,Transaksi!$A$2:$A$2001,"<"&EDATE($B54,1)) | E54: =C54-D54 | F54: =SUM(E$52:E54) | G54: =SUMIFS(Transaksi!$G$2:$G$2001,Transaksi!$A$2:$A$2001,">="&$B54,Transaksi!$A$2:$A$2001,"<"&EDATE($B54,1)) | H54: =SUMIFS(Transaksi!$H$2:$H$2001,Transaksi!$A$2:$A$2001,">="&$B54,Transaksi!$A$2:$A$2001,"<"&EDATE($B54,1)) | I54: =SUMIFS(Transaksi!$I$2:$I$2001,Transaksi!$A$2:$A$2001,">="&$B54,Transaksi!$A$2:$A$2001,"<"&EDATE($B54,1))
B55: =EDATE(Tetapan!$B$28,3) | C55: =SUMIFS(Transaksi!$G$2:$G$2001,Transaksi!$A$2:$A$2001,">="&$B55,Transaksi!$A$2:$A$2001,"<"&EDATE($B55,1))+SUMIFS(Transaksi!$H$2:$H$2001,Transaksi!$A$2:$A$2001,">="&$B55,Transaksi!$A$2:$A$2001,"<"&EDATE($B55,1))+SUMIFS(Transaksi!$I$2:$I$2001,Transaksi!$A$2:$A$2001,">="&$B55,Transaksi!$A$2:$A$2001,"<"&EDATE($B55,1)) | D55: =SUMIFS(Transaksi!$J$2:$J$2001,Transaksi!$A$2:$A$2001,">="&$B55,Transaksi!$A$2:$A$2001,"<"&EDATE($B55,1)) | E55: =C55-D55 | F55: =SUM(E$52:E55) | G55: =SUMIFS(Transaksi!$G$2:$G$2001,Transaksi!$A$2:$A$2001,">="&$B55,Transaksi!$A$2:$A$2001,"<"&EDATE($B55,1)) | H55: =SUMIFS(Transaksi!$H$2:$H$2001,Transaksi!$A$2:$A$2001,">="&$B55,Transaksi!$A$2:$A$2001,"<"&EDATE($B55,1)) | I55: =SUMIFS(Transaksi!$I$2:$I$2001,Transaksi!$A$2:$A$2001,">="&$B55,Transaksi!$A$2:$A$2001,"<"&EDATE($B55,1))
B56: =EDATE(Tetapan!$B$28,4) | C56: =SUMIFS(Transaksi!$G$2:$G$2001,Transaksi!$A$2:$A$2001,">="&$B56,Transaksi!$A$2:$A$2001,"<"&EDATE($B56,1))+SUMIFS(Transaksi!$H$2:$H$2001,Transaksi!$A$2:$A$2001,">="&$B56,Transaksi!$A$2:$A$2001,"<"&EDATE($B56,1))+SUMIFS(Transaksi!$I$2:$I$2001,Transaksi!$A$2:$A$2001,">="&$B56,Transaksi!$A$2:$A$2001,"<"&EDATE($B56,1)) | D56: =SUMIFS(Transaksi!$J$2:$J$2001,Transaksi!$A$2:$A$2001,">="&$B56,Transaksi!$A$2:$A$2001,"<"&EDATE($B56,1)) | E56: =C56-D56 | F56: =SUM(E$52:E56) | G56: =SUMIFS(Transaksi!$G$2:$G$2001,Transaksi!$A$2:$A$2001,">="&$B56,Transaksi!$A$2:$A$2001,"<"&EDATE($B56,1)) | H56: =SUMIFS(Transaksi!$H$2:$H$2001,Transaksi!$A$2:$A$2001,">="&$B56,Transaksi!$A$2:$A$2001,"<"&EDATE($B56,1)) | I56: =SUMIFS(Transaksi!$I$2:$I$2001,Transaksi!$A$2:$A$2001,">="&$B56,Transaksi!$A$2:$A$2001,"<"&EDATE($B56,1))
B57: =EDATE(Tetapan!$B$28,5) | C57: =SUMIFS(Transaksi!$G$2:$G$2001,Transaksi!$A$2:$A$2001,">="&$B57,Transaksi!$A$2:$A$2001,"<"&EDATE($B57,1))+SUMIFS(Transaksi!$H$2:$H$2001,Transaksi!$A$2:$A$2001,">="&$B57,Transaksi!$A$2:$A$2001,"<"&EDATE($B57,1))+SUMIFS(Transaksi!$I$2:$I$2001,Transaksi!$A$2:$A$2001,">="&$B57,Transaksi!$A$2:$A$2001,"<"&EDATE($B57,1)) | D57: =SUMIFS(Transaksi!$J$2:$J$2001,Transaksi!$A$2:$A$2001,">="&$B57,Transaksi!$A$2:$A$2001,"<"&EDATE($B57,1)) | E57: =C57-D57 | F57: =SUM(E$52:E57) | G57: =SUMIFS(Transaksi!$G$2:$G$2001,Transaksi!$A$2:$A$2001,">="&$B57,Transaksi!$A$2:$A$2001,"<"&EDATE($B57,1)) | H57: =SUMIFS(Transaksi!$H$2:$H$2001,Transaksi!$A$2:$A$2001,">="&$B57,Transaksi!$A$2:$A$2001,"<"&EDATE($B57,1)) | I57: =SUMIFS(Transaksi!$I$2:$I$2001,Transaksi!$A$2:$A$2001,">="&$B57,Transaksi!$A$2:$A$2001,"<"&EDATE($B57,1))
B58: =EDATE(Tetapan!$B$28,6) | C58: =SUMIFS(Transaksi!$G$2:$G$2001,Transaksi!$A$2:$A$2001,">="&$B58,Transaksi!$A$2:$A$2001,"<"&EDATE($B58,1))+SUMIFS(Transaksi!$H$2:$H$2001,Transaksi!$A$2:$A$2001,">="&$B58,Transaksi!$A$2:$A$2001,"<"&EDATE($B58,1))+SUMIFS(Transaksi!$I$2:$I$2001,Transaksi!$A$2:$A$2001,">="&$B58,Transaksi!$A$2:$A$2001,"<"&EDATE($B58,1)) | D58: =SUMIFS(Transaksi!$J$2:$J$2001,Transaksi!$A$2:$A$2001,">="&$B58,Transaksi!$A$2:$A$2001,"<"&EDATE($B58,1)) | E58: =C58-D58 | F58: =SUM(E$52:E58) | G58: =SUMIFS(Transaksi!$G$2:$G$2001,Transaksi!$A$2:$A$2001,">="&$B58,Transaksi!$A$2:$A$2001,"<"&EDATE($B58,1)) | H58: =SUMIFS(Transaksi!$H$2:$H$2001,Transaksi!$A$2:$A$2001,">="&$B58,Transaksi!$A$2:$A$2001,"<"&EDATE($B58,1)) | I58: =SUMIFS(Transaksi!$I$2:$I$2001,Transaksi!$A$2:$A$2001,">="&$B58,Transaksi!$A$2:$A$2001,"<"&EDATE($B58,1))
B59: =EDATE(Tetapan!$B$28,7) | C59: =SUMIFS(Transaksi!$G$2:$G$2001,Transaksi!$A$2:$A$2001,">="&$B59,Transaksi!$A$2:$A$2001,"<"&EDATE($B59,1))+SUMIFS(Transaksi!$H$2:$H$2001,Transaksi!$A$2:$A$2001,">="&$B59,Transaksi!$A$2:$A$2001,"<"&EDATE($B59,1))+SUMIFS(Transaksi!$I$2:$I$2001,Transaksi!$A$2:$A$2001,">="&$B59,Transaksi!$A$2:$A$2001,"<"&EDATE($B59,1)) | D59: =SUMIFS(Transaksi!$J$2:$J$2001,Transaksi!$A$2:$A$2001,">="&$B59,Transaksi!$A$2:$A$2001,"<"&EDATE($B59,1)) | E59: =C59-D59 | F59: =SUM(E$52:E59) | G59: =SUMIFS(Transaksi!$G$2:$G$2001,Transaksi!$A$2:$A$2001,">="&$B59,Transaksi!$A$2:$A$2001,"<"&EDATE($B59,1)) | H59: =SUMIFS(Transaksi!$H$2:$H$2001,Transaksi!$A$2:$A$2001,">="&$B59,Transaksi!$A$2:$A$2001,"<"&EDATE($B59,1)) | I59: =SUMIFS(Transaksi!$I$2:$I$2001,Transaksi!$A$2:$A$2001,">="&$B59,Transaksi!$A$2:$A$2001,"<"&EDATE($B59,1))
B60: =EDATE(Tetapan!$B$28,8) | C60: =SUMIFS(Transaksi!$G$2:$G$2001,Transaksi!$A$2:$A$2001,">="&$B60,Transaksi!$A$2:$A$2001,"<"&EDATE($B60,1))+SUMIFS(Transaksi!$H$2:$H$2001,Transaksi!$A$2:$A$2001,">="&$B60,Transaksi!$A$2:$A$2001,"<"&EDATE($B60,1))+SUMIFS(Transaksi!$I$2:$I$2001,Transaksi!$A$2:$A$2001,">="&$B60,Transaksi!$A$2:$A$2001,"<"&EDATE($B60,1)) | D60: =SUMIFS(Transaksi!$J$2:$J$2001,Transaksi!$A$2:$A$2001,">="&$B60,Transaksi!$A$2:$A$2001,"<"&EDATE($B60,1)) | E60: =C60-D60 | F60: =SUM(E$52:E60) | G60: =SUMIFS(Transaksi!$G$2:$G$2001,Transaksi!$A$2:$A$2001,">="&$B60,Transaksi!$A$2:$A$2001,"<"&EDATE($B60,1)) | H60: =SUMIFS(Transaksi!$H$2:$H$2001,Transaksi!$A$2:$A$2001,">="&$B60,Transaksi!$A$2:$A$2001,"<"&EDATE($B60,1)) | I60: =SUMIFS(Transaksi!$I$2:$I$2001,Transaksi!$A$2:$A$2001,">="&$B60,Transaksi!$A$2:$A$2001,"<"&EDATE($B60,1))
B61: =EDATE(Tetapan!$B$28,9) | C61: =SUMIFS(Transaksi!$G$2:$G$2001,Transaksi!$A$2:$A$2001,">="&$B61,Transaksi!$A$2:$A$2001,"<"&EDATE($B61,1))+SUMIFS(Transaksi!$H$2:$H$2001,Transaksi!$A$2:$A$2001,">="&$B61,Transaksi!$A$2:$A$2001,"<"&EDATE($B61,1))+SUMIFS(Transaksi!$I$2:$I$2001,Transaksi!$A$2:$A$2001,">="&$B61,Transaksi!$A$2:$A$2001,"<"&EDATE($B61,1)) | D61: =SUMIFS(Transaksi!$J$2:$J$2001,Transaksi!$A$2:$A$2001,">="&$B61,Transaksi!$A$2:$A$2001,"<"&EDATE($B61,1)) | E61: =C61-D61 | F61: =SUM(E$52:E61) | G61: =SUMIFS(Transaksi!$G$2:$G$2001,Transaksi!$A$2:$A$2001,">="&$B61,Transaksi!$A$2:$A$2001,"<"&EDATE($B61,1)) | H61: =SUMIFS(Transaksi!$H$2:$H$2001,Transaksi!$A$2:$A$2001,">="&$B61,Transaksi!$A$2:$A$2001,"<"&EDATE($B61,1)) | I61: =SUMIFS(Transaksi!$I$2:$I$2001,Transaksi!$A$2:$A$2001,">="&$B61,Transaksi!$A$2:$A$2001,"<"&EDATE($B61,1))
B62: =EDATE(Tetapan!$B$28,10) | C62: =SUMIFS(Transaksi!$G$2:$G$2001,Transaksi!$A$2:$A$2001,">="&$B62,Transaksi!$A$2:$A$2001,"<"&EDATE($B62,1))+SUMIFS(Transaksi!$H$2:$H$2001,Transaksi!$A$2:$A$2001,">="&$B62,Transaksi!$A$2:$A$2001,"<"&EDATE($B62,1))+SUMIFS(Transaksi!$I$2:$I$2001,Transaksi!$A$2:$A$2001,">="&$B62,Transaksi!$A$2:$A$2001,"<"&EDATE($B62,1)) | D62: =SUMIFS(Transaksi!$J$2:$J$2001,Transaksi!$A$2:$A$2001,">="&$B62,Transaksi!$A$2:$A$2001,"<"&EDATE($B62,1)) | E62: =C62-D62 | F62: =SUM(E$52:E62) | G62: =SUMIFS(Transaksi!$G$2:$G$2001,Transaksi!$A$2:$A$2001,">="&$B62,Transaksi!$A$2:$A$2001,"<"&EDATE($B62,1)) | H62: =SUMIFS(Transaksi!$H$2:$H$2001,Transaksi!$A$2:$A$2001,">="&$B62,Transaksi!$A$2:$A$2001,"<"&EDATE($B62,1)) | I62: =SUMIFS(Transaksi!$I$2:$I$2001,Transaksi!$A$2:$A$2001,">="&$B62,Transaksi!$A$2:$A$2001,"<"&EDATE($B62,1))
B63: =EDATE(Tetapan!$B$28,11) | C63: =SUMIFS(Transaksi!$G$2:$G$2001,Transaksi!$A$2:$A$2001,">="&$B63,Transaksi!$A$2:$A$2001,"<"&EDATE($B63,1))+SUMIFS(Transaksi!$H$2:$H$2001,Transaksi!$A$2:$A$2001,">="&$B63,Transaksi!$A$2:$A$2001,"<"&EDATE($B63,1))+SUMIFS(Transaksi!$I$2:$I$2001,Transaksi!$A$2:$A$2001,">="&$B63,Transaksi!$A$2:$A$2001,"<"&EDATE($B63,1)) | D63: =SUMIFS(Transaksi!$J$2:$J$2001,Transaksi!$A$2:$A$2001,">="&$B63,Transaksi!$A$2:$A$2001,"<"&EDATE($B63,1)) | E63: =C63-D63 | F63: =SUM(E$52:E63) | G63: =SUMIFS(Transaksi!$G$2:$G$2001,Transaksi!$A$2:$A$2001,">="&$B63,Transaksi!$A$2:$A$2001,"<"&EDATE($B63,1)) | H63: =SUMIFS(Transaksi!$H$2:$H$2001,Transaksi!$A$2:$A$2001,">="&$B63,Transaksi!$A$2:$A$2001,"<"&EDATE($B63,1)) | I63: =SUMIFS(Transaksi!$I$2:$I$2001,Transaksi!$A$2:$A$2001,">="&$B63,Transaksi!$A$2:$A$2001,"<"&EDATE($B63,1))
B64: =EDATE(Tetapan!$B$28,12) | C64: =SUMIFS(Transaksi!$G$2:$G$2001,Transaksi!$A$2:$A$2001,">="&$B64,Transaksi!$A$2:$A$2001,"<"&EDATE($B64,1))+SUMIFS(Transaksi!$H$2:$H$2001,Transaksi!$A$2:$A$2001,">="&$B64,Transaksi!$A$2:$A$2001,"<"&EDATE($B64,1))+SUMIFS(Transaksi!$I$2:$I$2001,Transaksi!$A$2:$A$2001,">="&$B64,Transaksi!$A$2:$A$2001,"<"&EDATE($B64,1)) | D64: =SUMIFS(Transaksi!$J$2:$J$2001,Transaksi!$A$2:$A$2001,">="&$B64,Transaksi!$A$2:$A$2001,"<"&EDATE($B64,1)) | E64: =C64-D64 | F64: =SUM(E$52:E64) | G64: =SUMIFS(Transaksi!$G$2:$G$2001,Transaksi!$A$2:$A$2001,">="&$B64,Transaksi!$A$2:$A$2001,"<"&EDATE($B64,1)) | H64: =SUMIFS(Transaksi!$H$2:$H$2001,Transaksi!$A$2:$A$2001,">="&$B64,Transaksi!$A$2:$A$2001,"<"&EDATE($B64,1)) | I64: =SUMIFS(Transaksi!$I$2:$I$2001,Transaksi!$A$2:$A$2001,">="&$B64,Transaksi!$A$2:$A$2001,"<"&EDATE($B64,1))
B65: =EDATE(Tetapan!$B$28,13) | C65: =SUMIFS(Transaksi!$G$2:$G$2001,Transaksi!$A$2:$A$2001,">="&$B65,Transaksi!$A$2:$A$2001,"<"&EDATE($B65,1))+SUMIFS(Transaksi!$H$2:$H$2001,Transaksi!$A$2:$A$2001,">="&$B65,Transaksi!$A$2:$A$2001,"<"&EDATE($B65,1))+SUMIFS(Transaksi!$I$2:$I$2001,Transaksi!$A$2:$A$2001,">="&$B65,Transaksi!$A$2:$A$2001,"<"&EDATE($B65,1)) | D65: =SUMIFS(Transaksi!$J$2:$J$2001,Transaksi!$A$2:$A$2001,">="&$B65,Transaksi!$A$2:$A$2001,"<"&EDATE($B65,1)) | E65: =C65-D65 | F65: =SUM(E$52:E65) | G65: =SUMIFS(Transaksi!$G$2:$G$2001,Transaksi!$A$2:$A$2001,">="&$B65,Transaksi!$A$2:$A$2001,"<"&EDATE($B65,1)) | H65: =SUMIFS(Transaksi!$H$2:$H$2001,Transaksi!$A$2:$A$2001,">="&$B65,Transaksi!$A$2:$A$2001,"<"&EDATE($B65,1)) | I65: =SUMIFS(Transaksi!$I$2:$I$2001,Transaksi!$A$2:$A$2001,">="&$B65,Transaksi!$A$2:$A$2001,"<"&EDATE($B65,1))
B66: =EDATE(Tetapan!$B$28,14) | C66: =SUMIFS(Transaksi!$G$2:$G$2001,Transaksi!$A$2:$A$2001,">="&$B66,Transaksi!$A$2:$A$2001,"<"&EDATE($B66,1))+SUMIFS(Transaksi!$H$2:$H$2001,Transaksi!$A$2:$A$2001,">="&$B66,Transaksi!$A$2:$A$2001,"<"&EDATE($B66,1))+SUMIFS(Transaksi!$I$2:$I$2001,Transaksi!$A$2:$A$2001,">="&$B66,Transaksi!$A$2:$A$2001,"<"&EDATE($B66,1)) | D66: =SUMIFS(Transaksi!$J$2:$J$2001,Transaksi!$A$2:$A$2001,">="&$B66,Transaksi!$A$2:$A$2001,"<"&EDATE($B66,1)) | E66: =C66-D66 | F66: =SUM(E$52:E66) | G66: =SUMIFS(Transaksi!$G$2:$G$2001,Transaksi!$A$2:$A$2001,">="&$B66,Transaksi!$A$2:$A$2001,"<"&EDATE($B66,1)) | H66: =SUMIFS(Transaksi!$H$2:$H$2001,Transaksi!$A$2:$A$2001,">="&$B66,Transaksi!$A$2:$A$2001,"<"&EDATE($B66,1)) | I66: =SUMIFS(Transaksi!$I$2:$I$2001,Transaksi!$A$2:$A$2001,">="&$B66,Transaksi!$A$2:$A$2001,"<"&EDATE($B66,1))
B67: =EDATE(Tetapan!$B$28,15) | C67: =SUMIFS(Transaksi!$G$2:$G$2001,Transaksi!$A$2:$A$2001,">="&$B67,Transaksi!$A$2:$A$2001,"<"&EDATE($B67,1))+SUMIFS(Transaksi!$H$2:$H$2001,Transaksi!$A$2:$A$2001,">="&$B67,Transaksi!$A$2:$A$2001,"<"&EDATE($B67,1))+SUMIFS(Transaksi!$I$2:$I$2001,Transaksi!$A$2:$A$2001,">="&$B67,Transaksi!$A$2:$A$2001,"<"&EDATE($B67,1)) | D67: =SUMIFS(Transaksi!$J$2:$J$2001,Transaksi!$A$2:$A$2001,">="&$B67,Transaksi!$A$2:$A$2001,"<"&EDATE($B67,1)) | E67: =C67-D67 | F67: =SUM(E$52:E67) | G67: =SUMIFS(Transaksi!$G$2:$G$2001,Transaksi!$A$2:$A$2001,">="&$B67,Transaksi!$A$2:$A$2001,"<"&EDATE($B67,1)) | H67: =SUMIFS(Transaksi!$H$2:$H$2001,Transaksi!$A$2:$A$2001,">="&$B67,Transaksi!$A$2:$A$2001,"<"&EDATE($B67,1)) | I67: =SUMIFS(Transaksi!$I$2:$I$2001,Transaksi!$A$2:$A$2001,">="&$B67,Transaksi!$A$2:$A$2001,"<"&EDATE($B67,1))
B68: =EDATE(Tetapan!$B$28,16) | C68: =SUMIFS(Transaksi!$G$2:$G$2001,Transaksi!$A$2:$A$2001,">="&$B68,Transaksi!$A$2:$A$2001,"<"&EDATE($B68,1))+SUMIFS(Transaksi!$H$2:$H$2001,Transaksi!$A$2:$A$2001,">="&$B68,Transaksi!$A$2:$A$2001,"<"&EDATE($B68,1))+SUMIFS(Transaksi!$I$2:$I$2001,Transaksi!$A$2:$A$2001,">="&$B68,Transaksi!$A$2:$A$2001,"<"&EDATE($B68,1)) | D68: =SUMIFS(Transaksi!$J$2:$J$2001,Transaksi!$A$2:$A$2001,">="&$B68,Transaksi!$A$2:$A$2001,"<"&EDATE($B68,1)) | E68: =C68-D68 | F68: =SUM(E$52:E68) | G68: =SUMIFS(Transaksi!$G$2:$G$2001,Transaksi!$A$2:$A$2001,">="&$B68,Transaksi!$A$2:$A$2001,"<"&EDATE($B68,1)) | H68: =SUMIFS(Transaksi!$H$2:$H$2001,Transaksi!$A$2:$A$2001,">="&$B68,Transaksi!$A$2:$A$2001,"<"&EDATE($B68,1)) | I68: =SUMIFS(Transaksi!$I$2:$I$2001,Transaksi!$A$2:$A$2001,">="&$B68,Transaksi!$A$2:$A$2001,"<"&EDATE($B68,1))
B69: =EDATE(Tetapan!$B$28,17) | C69: =SUMIFS(Transaksi!$G$2:$G$2001,Transaksi!$A$2:$A$2001,">="&$B69,Transaksi!$A$2:$A$2001,"<"&EDATE($B69,1))+SUMIFS(Transaksi!$H$2:$H$2001,Transaksi!$A$2:$A$2001,">="&$B69,Transaksi!$A$2:$A$2001,"<"&EDATE($B69,1))+SUMIFS(Transaksi!$I$2:$I$2001,Transaksi!$A$2:$A$2001,">="&$B69,Transaksi!$A$2:$A$2001,"<"&EDATE($B69,1)) | D69: =SUMIFS(Transaksi!$J$2:$J$2001,Transaksi!$A$2:$A$2001,">="&$B69,Transaksi!$A$2:$A$2001,"<"&EDATE($B69,1)) | E69: =C69-D69 | F69: =SUM(E$52:E69) | G69: =SUMIFS(Transaksi!$G$2:$G$2001,Transaksi!$A$2:$A$2001,">="&$B69,Transaksi!$A$2:$A$2001,"<"&EDATE($B69,1)) | H69: =SUMIFS(Transaksi!$H$2:$H$2001,Transaksi!$A$2:$A$2001,">="&$B69,Transaksi!$A$2:$A$2001,"<"&EDATE($B69,1)) | I69: =SUMIFS(Transaksi!$I$2:$I$2001,Transaksi!$A$2:$A$2001,">="&$B69,Transaksi!$A$2:$A$2001,"<"&EDATE($B69,1))
B70: =EDATE(Tetapan!$B$28,18) | C70: =SUMIFS(Transaksi!$G$2:$G$2001,Transaksi!$A$2:$A$2001,">="&$B70,Transaksi!$A$2:$A$2001,"<"&EDATE($B70,1))+SUMIFS(Transaksi!$H$2:$H$2001,Transaksi!$A$2:$A$2001,">="&$B70,Transaksi!$A$2:$A$2001,"<"&EDATE($B70,1))+SUMIFS(Transaksi!$I$2:$I$2001,Transaksi!$A$2:$A$2001,">="&$B70,Transaksi!$A$2:$A$2001,"<"&EDATE($B70,1)) | D70: =SUMIFS(Transaksi!$J$2:$J$2001,Transaksi!$A$2:$A$2001,">="&$B70,Transaksi!$A$2:$A$2001,"<"&EDATE($B70,1)) | E70: =C70-D70 | F70: =SUM(E$52:E70) | G70: =SUMIFS(Transaksi!$G$2:$G$2001,Transaksi!$A$2:$A$2001,">="&$B70,Transaksi!$A$2:$A$2001,"<"&EDATE($B70,1)) | H70: =SUMIFS(Transaksi!$H$2:$H$2001,Transaksi!$A$2:$A$2001,">="&$B70,Transaksi!$A$2:$A$2001,"<"&EDATE($B70,1)) | I70: =SUMIFS(Transaksi!$I$2:$I$2001,Transaksi!$A$2:$A$2001,">="&$B70,Transaksi!$A$2:$A$2001,"<"&EDATE($B70,1))
B71: Jumlah | C71: =SUM(C52:C70) | D71: =SUM(D52:D70) | E71: =SUM(E52:E70) | G71: =SUM(G52:G70) | H71: =SUM(H52:H70) | I71: =SUM(I52:I70)
B74: Perbelanjaan mengikut kategori
B75: Kategori | C75: Jumlah | D75: %
B76: =Tetapan!H9 | C76: =SUMIFS(Transaksi!$J$2:$J$2001,Transaksi!$D$2:$D$2001,B76) | D76: =IF(SUM(C$76:C$82)=0,0,C76/SUM(C$76:C$82)) | E76: =REPT("█",ROUND(D76*40,0))
B77: =Tetapan!H10 | C77: =SUMIFS(Transaksi!$J$2:$J$2001,Transaksi!$D$2:$D$2001,B77) | D77: =IF(SUM(C$76:C$82)=0,0,C77/SUM(C$76:C$82)) | E77: =REPT("█",ROUND(D77*40,0))
B78: =Tetapan!H11 | C78: =SUMIFS(Transaksi!$J$2:$J$2001,Transaksi!$D$2:$D$2001,B78) | D78: =IF(SUM(C$76:C$82)=0,0,C78/SUM(C$76:C$82)) | E78: =REPT("█",ROUND(D78*40,0))
B79: =Tetapan!H12 | C79: =SUMIFS(Transaksi!$J$2:$J$2001,Transaksi!$D$2:$D$2001,B79) | D79: =IF(SUM(C$76:C$82)=0,0,C79/SUM(C$76:C$82)) | E79: =REPT("█",ROUND(D79*40,0))
B80: =Tetapan!H13 | C80: =SUMIFS(Transaksi!$J$2:$J$2001,Transaksi!$D$2:$D$2001,B80) | D80: =IF(SUM(C$76:C$82)=0,0,C80/SUM(C$76:C$82)) | E80: =REPT("█",ROUND(D80*40,0))
B81: =Tetapan!H14 | C81: =SUMIFS(Transaksi!$J$2:$J$2001,Transaksi!$D$2:$D$2001,B81) | D81: =IF(SUM(C$76:C$82)=0,0,C81/SUM(C$76:C$82)) | E81: =REPT("█",ROUND(D81*40,0))
...

Sheet Harian
A1: Harian | N1: maksimum hari | O1: =MAX(Transaksi!$M$2:$M$2001)
A2: Setiap hari: semua wang masuk & keluar pada hari itu. Terbaru di atas. Auto daripada Transaksi. | N2: jumlah baris | O2: =SUM(P3:P402)
B3: Butiran | C3: Ahli | D3: Kategori | E3: Masuk | F3: Keluar | G3: Baki hujung hari | N3: 1 | O3: =IF(N3<=$O$1,$O$1-N3+1,"") | P3: =IF(O3="",0,COUNTIF(Transaksi!$M$2:$M$2001,O3)+1) | Q3: =1+SUM(P$2:P2)
A4: =IF(J4="E",IF(INDEX(Transaksi!$J$2:$J$2001,K4)>0,"↑","↓"),"") | B4: =IF(J4="H",CHOOSE(WEEKDAY(T4,2),"Isnin","Selasa","Rabu","Khamis","Jumaat","Sabtu","Ahad")&", "&DAY(T4)&" "&CHOOSE(MONTH(T4),"Jan","Feb","Mac","Apr","Mei","Jun","Jul","Ogo","Sep","Okt","Nov","Dis")&" "&YEAR(T4),IF(J4="E",IF(INDEX(Transaksi!$B$2:$B$2001,K4)="",INDEX(Transaksi!$C$2:$C$2001,K4)&" · "&INDEX(Transaksi!$D$2:$D$2001,K4),INDEX(Transaksi!$B$2:$B$2001,K4)),"")) | C4: =IF(J4="E",INDEX(Transaksi!$C$2:$C$2001,K4)&"","") | D4: =IF(J4="E",INDEX(Transaksi!$D$2:$D$2001,K4)&"","") | E4: =IF(J4="H",SUMIFS(Transaksi!$G$2:$G$2001,Transaksi!$M$2:$M$2001,"="&S4)+SUMIFS(Transaksi!$H$2:$H$2001,Transaksi!$M$2:$M$2001,"="&S4)+SUMIFS(Transaksi!$I$2:$I$2001,Transaksi!$M$2:$M$2001,"="&S4),IF(J4="E",IF(INDEX(Transaksi!$G$2:$G$2001,K4)+INDEX(Transaksi!$H$2:$H$2001,K4)+INDEX(Transaksi!$I$2:$I$2001,K4)=0,"",INDEX(Transaksi!$G$2:$G$2001,K4)+INDEX(Transaksi!$H$2:$H$2001,K4)+INDEX(Transaksi!$I$2:$I$2001,K4)),"")) | F4: =IF(J4="H",SUMIFS(Transaksi!$J$2:$J$2001,Transaksi!$M$2:$M$2001,"="&S4),IF(J4="E",IF(INDEX(Transaksi!$J$2:$J$2001,K4)=0,"",INDEX(Transaksi!$J$2:$J$2001,K4)),"")) | G4: =IF(J4="H",(SUMIFS(Transaksi!$G$2:$G$2001,Transaksi!$M$2:$M$2001,"<="&S4)+SUMIFS(Transaksi!$H$2:$H$2001,Transaksi!$M$2:$M$2001,"<="&S4)+SUMIFS(Transaksi!$I$2:$I$2001,Transaksi!$M$2:$M$2001,"<="&S4))-(SUMIFS(Transaksi!$J$2:$J$2001,Transaksi!$M$2:$M$2001,"<="&S4)),"") | I4: =IF(1>$O$2,"",MATCH(1,$Q$3:$Q$402,1)) | J4: =IF(I4="","",IF(1=INDEX($Q$3:$Q$402,I4),"H","E")) | K4: =IF(J4<>"E","",MATCH(S4,Transaksi!$M$2:$M$2001,0)+1-INDEX($Q$3:$Q$402,I4)-1) | N4: 2 | O4: =IF(N4<=$O$1,$O$1-N4+1,"") | P4: =IF(O4="",0,COUNTIF(Transaksi!$M$2:$M$2001,O4)+1) | Q4: =1+SUM(P$2:P3) | S4: =IF(I4="","",INDEX($O$3:$O$402,I4)) | T4: =IF(J4<>"H","",INDEX(Transaksi!$A$2:$A$2001,MATCH(S4,Transaksi!$M$2:$M$2001,0)))
A5: =IF(J5="E",IF(INDEX(Transaksi!$J$2:$J$2001,K5)>0,"↑","↓"),"") | B5: =IF(J5="H",CHOOSE(WEEKDAY(T5,2),"Isnin","Selasa","Rabu","Khamis","Jumaat","Sabtu","Ahad")&", "&DAY(T5)&" "&CHOOSE(MONTH(T5),"Jan","Feb","Mac","Apr","Mei","Jun","Jul","Ogo","Sep","Okt","Nov","Dis")&" "&YEAR(T5),IF(J5="E",IF(INDEX(Transaksi!$B$2:$B$2001,K5)="",INDEX(Transaksi!$C$2:$C$2001,K5)&" · "&INDEX(Transaksi!$D$2:$D$2001,K5),INDEX(Transaksi!$B$2:$B$2001,K5)),"")) | C5: =IF(J5="E",INDEX(Transaksi!$C$2:$C$2001,K5)&"","") | D5: =IF(J5="E",INDEX(Transaksi!$D$2:$D$2001,K5)&"","") | E5: =IF(J5="H",SUMIFS(Transaksi!$G$2:$G$2001,Transaksi!$M$2:$M$2001,"="&S5)+SUMIFS(Transaksi!$H$2:$H$2001,Transaksi!$M$2:$M$2001,"="&S5)+SUMIFS(Transaksi!$I$2:$I$2001,Transaksi!$M$2:$M$2001,"="&S5),IF(J5="E",IF(INDEX(Transaksi!$G$2:$G$2001,K5)+INDEX(Transaksi!$H$2:$H$2001,K5)+INDEX(Transaksi!$I$2:$I$2001,K5)=0,"",INDEX(Transaksi!$G$2:$G$2001,K5)+INDEX(Transaksi!$H$2:$H$2001,K5)+INDEX(Transaksi!$I$2:$I$2001,K5)),"")) | F5: =IF(J5="H",SUMIFS(Transaksi!$J$2:$J$2001,Transaksi!$M$2:$M$2001,"="&S5),IF(J5="E",IF(INDEX(Transaksi!$J$2:$J$2001,K5)=0,"",INDEX(Transaksi!$J$2:$J$2001,K5)),"")) | G5: =IF(J5="H",(SUMIFS(Transaksi!$G$2:$G$2001,Transaksi!$M$2:$M$2001,"<="&S5)+SUMIFS(Transaksi!$H$2:$H$2001,Transaksi!$M$2:$M$2001,"<="&S5)+SUMIFS(Transaksi!$I$2:$I$2001,Transaksi!$M$2:$M$2001,"<="&S5))-(SUMIFS(Transaksi!$J$2:$J$2001,Transaksi!$M$2:$M$2001,"<="&S5)),"") | I5: =IF(2>$O$2,"",MATCH(2,$Q$3:$Q$402,1)) | J5: =IF(I5="","",IF(2=INDEX($Q$3:$Q$402,I5),"H","E")) | K5: =IF(J5<>"E","",MATCH(S5,Transaksi!$M$2:$M$2001,0)+2-INDEX($Q$3:$Q$402,I5)-1) | N5: 3 | O5: =IF(N5<=$O$1,$O$1-N5+1,"") | P5: =IF(O5="",0,COUNTIF(Transaksi!$M$2:$M$2001,O5)+1) | Q5: =1+SUM(P$2:P4) | S5: =IF(I5="","",INDEX($O$3:$O$402,I5)) | T5: =IF(J5<>"H","",INDEX(Transaksi!$A$2:$A$2001,MATCH(S5,Transaksi!$M$2:$M$2001,0)))
A6: =IF(J6="E",IF(INDEX(Transaksi!$J$2:$J$2001,K6)>0,"↑","↓"),"") | B6: =IF(J6="H",CHOOSE(WEEKDAY(T6,2),"Isnin","Selasa","Rabu","Khamis","Jumaat","Sabtu","Ahad")&", "&DAY(T6)&" "&CHOOSE(MONTH(T6),"Jan","Feb","Mac","Apr","Mei","Jun","Jul","Ogo","Sep","Okt","Nov","Dis")&" "&YEAR(T6),IF(J6="E",IF(INDEX(Transaksi!$B$2:$B$2001,K6)="",INDEX(Transaksi!$C$2:$C$2001,K6)&" · "&INDEX(Transaksi!$D$2:$D$2001,K6),INDEX(Transaksi!$B$2:$B$2001,K6)),"")) | C6: =IF(J6="E",INDEX(Transaksi!$C$2:$C$2001,K6)&"","") | D6: =IF(J6="E",INDEX(Transaksi!$D$2:$D$2001,K6)&"","") | E6: =IF(J6="H",SUMIFS(Transaksi!$G$2:$G$2001,Transaksi!$M$2:$M$2001,"="&S6)+SUMIFS(Transaksi!$H$2:$H$2001,Transaksi!$M$2:$M$2001,"="&S6)+SUMIFS(Transaksi!$I$2:$I$2001,Transaksi!$M$2:$M$2001,"="&S6),IF(J6="E",IF(INDEX(Transaksi!$G$2:$G$2001,K6)+INDEX(Transaksi!$H$2:$H$2001,K6)+INDEX(Transaksi!$I$2:$I$2001,K6)=0,"",INDEX(Transaksi!$G$2:$G$2001,K6)+INDEX(Transaksi!$H$2:$H$2001,K6)+INDEX(Transaksi!$I$2:$I$2001,K6)),"")) | F6: =IF(J6="H",SUMIFS(Transaksi!$J$2:$J$2001,Transaksi!$M$2:$M$2001,"="&S6),IF(J6="E",IF(INDEX(Transaksi!$J$2:$J$2001,K6)=0,"",INDEX(Transaksi!$J$2:$J$2001,K6)),"")) | G6: =IF(J6="H",(SUMIFS(Transaksi!$G$2:$G$2001,Transaksi!$M$2:$M$2001,"<="&S6)+SUMIFS(Transaksi!$H$2:$H$2001,Transaksi!$M$2:$M$2001,"<="&S6)+SUMIFS(Transaksi!$I$2:$I$2001,Transaksi!$M$2:$M$2001,"<="&S6))-(SUMIFS(Transaksi!$J$2:$J$2001,Transaksi!$M$2:$M$2001,"<="&S6)),"") | I6: =IF(3>$O$2,"",MATCH(3,$Q$3:$Q$402,1)) | J6: =IF(I6="","",IF(3=INDEX($Q$3:$Q$402,I6),"H","E")) | K6: =IF(J6<>"E","",MATCH(S6,Transaksi!$M$2:$M$2001,0)+3-INDEX($Q$3:$Q$402,I6)-1) | N6: 4 | O6: =IF(N6<=$O$1,$O$1-N6+1,"") | P6: =IF(O6="",0,COUNTIF(Transaksi!$M$2:$M$2001,O6)+1) | Q6: =1+SUM(P$2:P5) | S6: =IF(I6="","",INDEX($O$3:$O$402,I6)) | T6: =IF(J6<>"H","",INDEX(Transaksi!$A$2:$A$2001,MATCH(S6,Transaksi!$M$2:$M$2001,0)))
A7: =IF(J7="E",IF(INDEX(Transaksi!$J$2:$J$2001,K7)>0,"↑","↓"),"") | B7: =IF(J7="H",CHOOSE(WEEKDAY(T7,2),"Isnin","Selasa","Rabu","Khamis","Jumaat","Sabtu","Ahad")&", "&DAY(T7)&" "&CHOOSE(MONTH(T7),"Jan","Feb","Mac","Apr","Mei","Jun","Jul","Ogo","Sep","Okt","Nov","Dis")&" "&YEAR(T7),IF(J7="E",IF(INDEX(Transaksi!$B$2:$B$2001,K7)="",INDEX(Transaksi!$C$2:$C$2001,K7)&" · "&INDEX(Transaksi!$D$2:$D$2001,K7),INDEX(Transaksi!$B$2:$B$2001,K7)),"")) | C7: =IF(J7="E",INDEX(Transaksi!$C$2:$C$2001,K7)&"","") | D7: =IF(J7="E",INDEX(Transaksi!$D$2:$D$2001,K7)&"","") | E7: =IF(J7="H",SUMIFS(Transaksi!$G$2:$G$2001,Transaksi!$M$2:$M$2001,"="&S7)+SUMIFS(Transaksi!$H$2:$H$2001,Transaksi!$M$2:$M$2001,"="&S7)+SUMIFS(Transaksi!$I$2:$I$2001,Transaksi!$M$2:$M$2001,"="&S7),IF(J7="E",IF(INDEX(Transaksi!$G$2:$G$2001,K7)+INDEX(Transaksi!$H$2:$H$2001,K7)+INDEX(Transaksi!$I$2:$I$2001,K7)=0,"",INDEX(Transaksi!$G$2:$G$2001,K7)+INDEX(Transaksi!$H$2:$H$2001,K7)+INDEX(Transaksi!$I$2:$I$2001,K7)),"")) | F7: =IF(J7="H",SUMIFS(Transaksi!$J$2:$J$2001,Transaksi!$M$2:$M$2001,"="&S7),IF(J7="E",IF(INDEX(Transaksi!$J$2:$J$2001,K7)=0,"",INDEX(Transaksi!$J$2:$J$2001,K7)),"")) | G7: =IF(J7="H",(SUMIFS(Transaksi!$G$2:$G$2001,Transaksi!$M$2:$M$2001,"<="&S7)+SUMIFS(Transaksi!$H$2:$H$2001,Transaksi!$M$2:$M$2001,"<="&S7)+SUMIFS(Transaksi!$I$2:$I$2001,Transaksi!$M$2:$M$2001,"<="&S7))-(SUMIFS(Transaksi!$J$2:$J$2001,Transaksi!$M$2:$M$2001,"<="&S7)),"") | I7: =IF(4>$O$2,"",MATCH(4,$Q$3:$Q$402,1)) | J7: =IF(I7="","",IF(4=INDEX($Q$3:$Q$402,I7),"H","E")) | K7: =IF(J7<>"E","",MATCH(S7,Transaksi!$M$2:$M$2001,0)+4-INDEX($Q$3:$Q$402,I7)-1) | N7: 5 | O7: =IF(N7<=$O$1,$O$1-N7+1,"") | P7: =IF(O7="",0,COUNTIF(Transaksi!$M$2:$M$2001,O7)+1) | Q7: =1+SUM(P$2:P6) | S7: =IF(I7="","",INDEX($O$3:$O$402,I7)) | T7: =IF(J7<>"H","",INDEX(Transaksi!$A$2:$A$2001,MATCH(S7,Transaksi!$M$2:$M$2001,0)))
A8: =IF(J8="E",IF(INDEX(Transaksi!$J$2:$J$2001,K8)>0,"↑","↓"),"") | B8: =IF(J8="H",CHOOSE(WEEKDAY(T8,2),"Isnin","Selasa","Rabu","Khamis","Jumaat","Sabtu","Ahad")&", "&DAY(T8)&" "&CHOOSE(MONTH(T8),"Jan","Feb","Mac","Apr","Mei","Jun","Jul","Ogo","Sep","Okt","Nov","Dis")&" "&YEAR(T8),IF(J8="E",IF(INDEX(Transaksi!$B$2:$B$2001,K8)="",INDEX(Transaksi!$C$2:$C$2001,K8)&" · "&INDEX(Transaksi!$D$2:$D$2001,K8),INDEX(Transaksi!$B$2:$B$2001,K8)),"")) | C8: =IF(J8="E",INDEX(Transaksi!$C$2:$C$2001,K8)&"","") | D8: =IF(J8="E",INDEX(Transaksi!$D$2:$D$2001,K8)&"","") | E8: =IF(J8="H",SUMIFS(Transaksi!$G$2:$G$2001,Transaksi!$M$2:$M$2001,"="&S8)+SUMIFS(Transaksi!$H$2:$H$2001,Transaksi!$M$2:$M$2001,"="&S8)+SUMIFS(Transaksi!$I$2:$I$2001,Transaksi!$M$2:$M$2001,"="&S8),IF(J8="E",IF(INDEX(Transaksi!$G$2:$G$2001,K8)+INDEX(Transaksi!$H$2:$H$2001,K8)+INDEX(Transaksi!$I$2:$I$2001,K8)=0,"",INDEX(Transaksi!$G$2:$G$2001,K8)+INDEX(Transaksi!$H$2:$H$2001,K8)+INDEX(Transaksi!$I$2:$I$2001,K8)),"")) | F8: =IF(J8="H",SUMIFS(Transaksi!$J$2:$J$2001,Transaksi!$M$2:$M$2001,"="&S8),IF(J8="E",IF(INDEX(Transaksi!$J$2:$J$2001,K8)=0,"",INDEX(Transaksi!$J$2:$J$2001,K8)),"")) | G8: =IF(J8="H",(SUMIFS(Transaksi!$G$2:$G$2001,Transaksi!$M$2:$M$2001,"<="&S8)+SUMIFS(Transaksi!$H$2:$H$2001,Transaksi!$M$2:$M$2001,"<="&S8)+SUMIFS(Transaksi!$I$2:$I$2001,Transaksi!$M$2:$M$2001,"<="&S8))-(SUMIFS(Transaksi!$J$2:$J$2001,Transaksi!$M$2:$M$2001,"<="&S8)),"") | I8: =IF(5>$O$2,"",MATCH(5,$Q$3:$Q$402,1)) | J8: =IF(I8="","",IF(5=INDEX($Q$3:$Q$402,I8),"H","E")) | K8: =IF(J8<>"E","",MATCH(S8,Transaksi!$M$2:$M$2001,0)+5-INDEX($Q$3:$Q$402,I8)-1) | N8: 6 | O8: =IF(N8<=$O$1,$O$1-N8+1,"") | P8: =IF(O8="",0,COUNTIF(Transaksi!$M$2:$M$2001,O8)+1) | Q8: =1+SUM(P$2:P7) | S8: =IF(I8="","",INDEX($O$3:$O$402,I8)) | T8: =IF(J8<>"H","",INDEX(Transaksi!$A$2:$A$2001,MATCH(S8,Transaksi!$M$2:$M$2001,0)))
A9: =IF(J9="E",IF(INDEX(Transaksi!$J$2:$J$2001,K9)>0,"↑","↓"),"") | B9: =IF(J9="H",CHOOSE(WEEKDAY(T9,2),"Isnin","Selasa","Rabu","Khamis","Jumaat","Sabtu","Ahad")&", "&DAY(T9)&" "&CHOOSE(MONTH(T9),"Jan","Feb","Mac","Apr","Mei","Jun","Jul","Ogo","Sep","Okt","Nov","Dis")&" "&YEAR(T9),IF(J9="E",IF(INDEX(Transaksi!$B$2:$B$2001,K9)="",INDEX(Transaksi!$C$2:$C$2001,K9)&" · "&INDEX(Transaksi!$D$2:$D$2001,K9),INDEX(Transaksi!$B$2:$B$2001,K9)),"")) | C9: =IF(J9="E",INDEX(Transaksi!$C$2:$C$2001,K9)&"","") | D9: =IF(J9="E",INDEX(Transaksi!$D$2:$D$2001,K9)&"","") | E9: =IF(J9="H",SUMIFS(Transaksi!$G$2:$G$2001,Transaksi!$M$2:$M$2001,"="&S9)+SUMIFS(Transaksi!$H$2:$H$2001,Transaksi!$M$2:$M$2001,"="&S9)+SUMIFS(Transaksi!$I$2:$I$2001,Transaksi!$M$2:$M$2001,"="&S9),IF(J9="E",IF(INDEX(Transaksi!$G$2:$G$2001,K9)+INDEX(Transaksi!$H$2:$H$2001,K9)+INDEX(Transaksi!$I$2:$I$2001,K9)=0,"",INDEX(Transaksi!$G$2:$G$2001,K9)+INDEX(Transaksi!$H$2:$H$2001,K9)+INDEX(Transaksi!$I$2:$I$2001,K9)),"")) | F9: =IF(J9="H",SUMIFS(Transaksi!$J$2:$J$2001,Transaksi!$M$2:$M$2001,"="&S9),IF(J9="E",IF(INDEX(Transaksi!$J$2:$J$2001,K9)=0,"",INDEX(Transaksi!$J$2:$J$2001,K9)),"")) | G9: =IF(J9="H",(SUMIFS(Transaksi!$G$2:$G$2001,Transaksi!$M$2:$M$2001,"<="&S9)+SUMIFS(Transaksi!$H$2:$H$2001,Transaksi!$M$2:$M$2001,"<="&S9)+SUMIFS(Transaksi!$I$2:$I$2001,Transaksi!$M$2:$M$2001,"<="&S9))-(SUMIFS(Transaksi!$J$2:$J$2001,Transaksi!$M$2:$M$2001,"<="&S9)),"") | I9: =IF(6>$O$2,"",MATCH(6,$Q$3:$Q$402,1)) | J9: =IF(I9="","",IF(6=INDEX($Q$3:$Q$402,I9),"H","E")) | K9: =IF(J9<>"E","",MATCH(S9,Transaksi!$M$2:$M$2001,0)+6-INDEX($Q$3:$Q$402,I9)-1) | N9: 7 | O9: =IF(N9<=$O$1,$O$1-N9+1,"") | P9: =IF(O9="",0,COUNTIF(Transaksi!$M$2:$M$2001,O9)+1) | Q9: =1+SUM(P$2:P8) | S9: =IF(I9="","",INDEX($O$3:$O$402,I9)) | T9: =IF(J9<>"H","",INDEX(Transaksi!$A$2:$A$2001,MATCH(S9,Transaksi!$M$2:$M$2001,0)))
A10: =IF(J10="E",IF(INDEX(Transaksi!$J$2:$J$2001,K10)>0,"↑","↓"),"") | B10: =IF(J10="H",CHOOSE(WEEKDAY(T10,2),"Isnin","Selasa","Rabu","Khamis","Jumaat","Sabtu","Ahad")&", "&DAY(T10)&" "&CHOOSE(MONTH(T10),"Jan","Feb","Mac","Apr","Mei","Jun","Jul","Ogo","Sep","Okt","Nov","Dis")&" "&YEAR(T10),IF(J10="E",IF(INDEX(Transaksi!$B$2:$B$2001,K10)="",INDEX(Transaksi!$C$2:$C$2001,K10)&" · "&INDEX(Transaksi!$D$2:$D$2001,K10),INDEX(Transaksi!$B$2:$B$2001,K10)),"")) | C10: =IF(J10="E",INDEX(Transaksi!$C$2:$C$2001,K10)&"","") | D10: =IF(J10="E",INDEX(Transaksi!$D$2:$D$2001,K10)&"","") | E10: =IF(J10="H",SUMIFS(Transaksi!$G$2:$G$2001,Transaksi!$M$2:$M$2001,"="&S10)+SUMIFS(Transaksi!$H$2:$H$2001,Transaksi!$M$2:$M$2001,"="&S10)+SUMIFS(Transaksi!$I$2:$I$2001,Transaksi!$M$2:$M$2001,"="&S10),IF(J10="E",IF(INDEX(Transaksi!$G$2:$G$2001,K10)+INDEX(Transaksi!$H$2:$H$2001,K10)+INDEX(Transaksi!$I$2:$I$2001,K10)=0,"",INDEX(Transaksi!$G$2:$G$2001,K10)+INDEX(Transaksi!$H$2:$H$2001,K10)+INDEX(Transaksi!$I$2:$I$2001,K10)),"")) | F10: =IF(J10="H",SUMIFS(Transaksi!$J$2:$J$2001,Transaksi!$M$2:$M$2001,"="&S10),IF(J10="E",IF(INDEX(Transaksi!$J$2:$J$2001,K10)=0,"",INDEX(Transaksi!$J$2:$J$2001,K10)),"")) | G10: =IF(J10="H",(SUMIFS(Transaksi!$G$2:$G$2001,Transaksi!$M$2:$M$2001,"<="&S10)+SUMIFS(Transaksi!$H$2:$H$2001,Transaksi!$M$2:$M$2001,"<="&S10)+SUMIFS(Transaksi!$I$2:$I$2001,Transaksi!$M$2:$M$2001,"<="&S10))-(SUMIFS(Transaksi!$J$2:$J$2001,Transaksi!$M$2:$M$2001,"<="&S10)),"") | I10: =IF(7>$O$2,"",MATCH(7,$Q$3:$Q$402,1)) | J10: =IF(I10="","",IF(7=INDEX($Q$3:$Q$402,I10),"H","E")) | K10: =IF(J10<>"E","",MATCH(S10,Transaksi!$M$2:$M$2001,0)+7-INDEX($Q$3:$Q$402,I10)-1) | N10: 8 | O10: =IF(N10<=$O$1,$O$1-N10+1,"") | P10: =IF(O10="",0,COUNTIF(Transaksi!$M$2:$M$2001,O10)+1) | Q10: =1+SUM(P$2:P9) | S10: =IF(I10="","",INDEX($O$3:$O$402,I10)) | T10: =IF(J10<>"H","",INDEX(Transaksi!$A$2:$A$2001,MATCH(S10,Transaksi!$M$2:$M$2001,0)))
A11: =IF(J11="E",IF(INDEX(Transaksi!$J$2:$J$2001,K11)>0,"↑","↓"),"") | B11: =IF(J11="H",CHOOSE(WEEKDAY(T11,2),"Isnin","Selasa","Rabu","Khamis","Jumaat","Sabtu","Ahad")&", "&DAY(T11)&" "&CHOOSE(MONTH(T11),"Jan","Feb","Mac","Apr","Mei","Jun","Jul","Ogo","Sep","Okt","Nov","Dis")&" "&YEAR(T11),IF(J11="E",IF(INDEX(Transaksi!$B$2:$B$2001,K11)="",INDEX(Transaksi!$C$2:$C$2001,K11)&" · "&INDEX(Transaksi!$D$2:$D$2001,K11),INDEX(Transaksi!$B$2:$B$2001,K11)),"")) | C11: =IF(J11="E",INDEX(Transaksi!$C$2:$C$2001,K11)&"","") | D11: =IF(J11="E",INDEX(Transaksi!$D$2:$D$2001,K11)&"","") | E11: =IF(J11="H",SUMIFS(Transaksi!$G$2:$G$2001,Transaksi!$M$2:$M$2001,"="&S11)+SUMIFS(Transaksi!$H$2:$H$2001,Transaksi!$M$2:$M$2001,"="&S11)+SUMIFS(Transaksi!$I$2:$I$2001,Transaksi!$M$2:$M$2001,"="&S11),IF(J11="E",IF(INDEX(Transaksi!$G$2:$G$2001,K11)+INDEX(Transaksi!$H$2:$H$2001,K11)+INDEX(Transaksi!$I$2:$I$2001,K11)=0,"",INDEX(Transaksi!$G$2:$G$2001,K11)+INDEX(Transaksi!$H$2:$H$2001,K11)+INDEX(Transaksi!$I$2:$I$2001,K11)),"")) | F11: =IF(J11="H",SUMIFS(Transaksi!$J$2:$J$2001,Transaksi!$M$2:$M$2001,"="&S11),IF(J11="E",IF(INDEX(Transaksi!$J$2:$J$2001,K11)=0,"",INDEX(Transaksi!$J$2:$J$2001,K11)),"")) | G11: =IF(J11="H",(SUMIFS(Transaksi!$G$2:$G$2001,Transaksi!$M$2:$M$2001,"<="&S11)+SUMIFS(Transaksi!$H$2:$H$2001,Transaksi!$M$2:$M$2001,"<="&S11)+SUMIFS(Transaksi!$I$2:$I$2001,Transaksi!$M$2:$M$2001,"<="&S11))-(SUMIFS(Transaksi!$J$2:$J$2001,Transaksi!$M$2:$M$2001,"<="&S11)),"") | I11: =IF(8>$O$2,"",MATCH(8,$Q$3:$Q$402,1)) | J11: =IF(I11="","",IF(8=INDEX($Q$3:$Q$402,I11),"H","E")) | K11: =IF(J11<>"E","",MATCH(S11,Transaksi!$M$2:$M$2001,0)+8-INDEX($Q$3:$Q$402,I11)-1) | N11: 9 | O11: =IF(N11<=$O$1,$O$1-N11+1,"") | P11: =IF(O11="",0,COUNTIF(Transaksi!$M$2:$M$2001,O11)+1) | Q11: =1+SUM(P$2:P10) | S11: =IF(I11="","",INDEX($O$3:$O$402,I11)) | T11: =IF(J11<>"H","",INDEX(Transaksi!$A$2:$A$2001,MATCH(S11,Transaksi!$M$2:$M$2001,0)))
A12: =IF(J12="E",IF(INDEX(Transaksi!$J$2:$J$2001,K12)>0,"↑","↓"),"") | B12: =IF(J12="H",CHOOSE(WEEKDAY(T12,2),"Isnin","Selasa","Rabu","Khamis","Jumaat","Sabtu","Ahad")&", "&DAY(T12)&" "&CHOOSE(MONTH(T12),"Jan","Feb","Mac","Apr","Mei","Jun","Jul","Ogo","Sep","Okt","Nov","Dis")&" "&YEAR(T12),IF(J12="E",IF(INDEX(Transaksi!$B$2:$B$2001,K12)="",INDEX(Transaksi!$C$2:$C$2001,K12)&" · "&INDEX(Transaksi!$D$2:$D$2001,K12),INDEX(Transaksi!$B$2:$B$2001,K12)),"")) | C12: =IF(J12="E",INDEX(Transaksi!$C$2:$C$2001,K12)&"","") | D12: =IF(J12="E",INDEX(Transaksi!$D$2:$D$2001,K12)&"","") | E12: =IF(J12="H",SUMIFS(Transaksi!$G$2:$G$2001,Transaksi!$M$2:$M$2001,"="&S12)+SUMIFS(Transaksi!$H$2:$H$2001,Transaksi!$M$2:$M$2001,"="&S12)+SUMIFS(Transaksi!$I$2:$I$2001,Transaksi!$M$2:$M$2001,"="&S12),IF(J12="E",IF(INDEX(Transaksi!$G$2:$G$2001,K12)+INDEX(Transaksi!$H$2:$H$2001,K12)+INDEX(Transaksi!$I$2:$I$2001,K12)=0,"",INDEX(Transaksi!$G$2:$G$2001,K12)+INDEX(Transaksi!$H$2:$H$2001,K12)+INDEX(Transaksi!$I$2:$I$2001,K12)),"")) | F12: =IF(J12="H",SUMIFS(Transaksi!$J$2:$J$2001,Transaksi!$M$2:$M$2001,"="&S12),IF(J12="E",IF(INDEX(Transaksi!$J$2:$J$2001,K12)=0,"",INDEX(Transaksi!$J$2:$J$2001,K12)),"")) | G12: =IF(J12="H",(SUMIFS(Transaksi!$G$2:$G$2001,Transaksi!$M$2:$M$2001,"<="&S12)+SUMIFS(Transaksi!$H$2:$H$2001,Transaksi!$M$2:$M$2001,"<="&S12)+SUMIFS(Transaksi!$I$2:$I$2001,Transaksi!$M$2:$M$2001,"<="&S12))-(SUMIFS(Transaksi!$J$2:$J$2001,Transaksi!$M$2:$M$2001,"<="&S12)),"") | I12: =IF(9>$O$2,"",MATCH(9,$Q$3:$Q$402,1)) | J12: =IF(I12="","",IF(9=INDEX($Q$3:$Q$402,I12),"H","E")) | K12: =IF(J12<>"E","",MATCH(S12,Transaksi!$M$2:$M$2001,0)+9-INDEX($Q$3:$Q$402,I12)-1) | N12: 10 | O12: =IF(N12<=$O$1,$O$1-N12+1,"") | P12: =IF(O12="",0,COUNTIF(Transaksi!$M$2:$M$2001,O12)+1) | Q12: =1+SUM(P$2:P11) | S12: =IF(I12="","",INDEX($O$3:$O$402,I12)) | T12: =IF(J12<>"H","",INDEX(Transaksi!$A$2:$A$2001,MATCH(S12,Transaksi!$M$2:$M$2001,0)))
A13: =IF(J13="E",IF(INDEX(Transaksi!$J$2:$J$2001,K13)>0,"↑","↓"),"") | B13: =IF(J13="H",CHOOSE(WEEKDAY(T13,2),"Isnin","Selasa","Rabu","Khamis","Jumaat","Sabtu","Ahad")&", "&DAY(T13)&" "&CHOOSE(MONTH(T13),"Jan","Feb","Mac","Apr","Mei","Jun","Jul","Ogo","Sep","Okt","Nov","Dis")&" "&YEAR(T13),IF(J13="E",IF(INDEX(Transaksi!$B$2:$B$2001,K13)="",INDEX(Transaksi!$C$2:$C$2001,K13)&" · "&INDEX(Transaksi!$D$2:$D$2001,K13),INDEX(Transaksi!$B$2:$B$2001,K13)),"")) | C13: =IF(J13="E",INDEX(Transaksi!$C$2:$C$2001,K13)&"","") | D13: =IF(J13="E",INDEX(Transaksi!$D$2:$D$2001,K13)&"","") | E13: =IF(J13="H",SUMIFS(Transaksi!$G$2:$G$2001,Transaksi!$M$2:$M$2001,"="&S13)+SUMIFS(Transaksi!$H$2:$H$2001,Transaksi!$M$2:$M$2001,"="&S13)+SUMIFS(Transaksi!$I$2:$I$2001,Transaksi!$M$2:$M$2001,"="&S13),IF(J13="E",IF(INDEX(Transaksi!$G$2:$G$2001,K13)+INDEX(Transaksi!$H$2:$H$2001,K13)+INDEX(Transaksi!$I$2:$I$2001,K13)=0,"",INDEX(Transaksi!$G$2:$G$2001,K13)+INDEX(Transaksi!$H$2:$H$2001,K13)+INDEX(Transaksi!$I$2:$I$2001,K13)),"")) | F13: =IF(J13="H",SUMIFS(Transaksi!$J$2:$J$2001,Transaksi!$M$2:$M$2001,"="&S13),IF(J13="E",IF(INDEX(Transaksi!$J$2:$J$2001,K13)=0,"",INDEX(Transaksi!$J$2:$J$2001,K13)),"")) | G13: =IF(J13="H",(SUMIFS(Transaksi!$G$2:$G$2001,Transaksi!$M$2:$M$2001,"<="&S13)+SUMIFS(Transaksi!$H$2:$H$2001,Transaksi!$M$2:$M$2001,"<="&S13)+SUMIFS(Transaksi!$I$2:$I$2001,Transaksi!$M$2:$M$2001,"<="&S13))-(SUMIFS(Transaksi!$J$2:$J$2001,Transaksi!$M$2:$M$2001,"<="&S13)),"") | I13: =IF(10>$O$2,"",MATCH(10,$Q$3:$Q$402,1)) | J13: =IF(I13="","",IF(10=INDEX($Q$3:$Q$402,I13),"H","E")) | K13: =IF(J13<>"E","",MATCH(S13,Transaksi!$M$2:$M$2001,0)+10-INDEX($Q$3:$Q$402,I13)-1) | N13: 11 | O13: =IF(N13<=$O$1,$O$1-N13+1,"") | P13: =IF(O13="",0,COUNTIF(Transaksi!$M$2:$M$2001,O13)+1) | Q13: =1+SUM(P$2:P12) | S13: =IF(I13="","",INDEX($O$3:$O$402,I13)) | T13: =IF(J13<>"H","",INDEX(Transaksi!$A$2:$A$2001,MATCH(S13,Transaksi!$M$2:$M$2001,0)))
A14: =IF(J14="E",IF(INDEX(Transaksi!$J$2:$J$2001,K14)>0,"↑","↓"),"") | B14: =IF(J14="H",CHOOSE(WEEKDAY(T14,2),"Isnin","Selasa","Rabu","Khamis","Jumaat","Sabtu","Ahad")&", "&DAY(T14)&" "&CHOOSE(MONTH(T14),"Jan","Feb","Mac","Apr","Mei","Jun","Jul","Ogo","Sep","Okt","Nov","Dis")&" "&YEAR(T14),IF(J14="E",IF(INDEX(Transaksi!$B$2:$B$2001,K14)="",INDEX(Transaksi!$C$2:$C$2001,K14)&" · "&INDEX(Transaksi!$D$2:$D$2001,K14),INDEX(Transaksi!$B$2:$B$2001,K14)),"")) | C14: =IF(J14="E",INDEX(Transaksi!$C$2:$C$2001,K14)&"","") | D14: =IF(J14="E",INDEX(Transaksi!$D$2:$D$2001,K14)&"","") | E14: =IF(J14="H",SUMIFS(Transaksi!$G$2:$G$2001,Transaksi!$M$2:$M$2001,"="&S14)+SUMIFS(Transaksi!$H$2:$H$2001,Transaksi!$M$2:$M$2001,"="&S14)+SUMIFS(Transaksi!$I$2:$I$2001,Transaksi!$M$2:$M$2001,"="&S14),IF(J14="E",IF(INDEX(Transaksi!$G$2:$G$2001,K14)+INDEX(Transaksi!$H$2:$H$2001,K14)+INDEX(Transaksi!$I$2:$I$2001,K14)=0,"",INDEX(Transaksi!$G$2:$G$2001,K14)+INDEX(Transaksi!$H$2:$H$2001,K14)+INDEX(Transaksi!$I$2:$I$2001,K14)),"")) | F14: =IF(J14="H",SUMIFS(Transaksi!$J$2:$J$2001,Transaksi!$M$2:$M$2001,"="&S14),IF(J14="E",IF(INDEX(Transaksi!$J$2:$J$2001,K14)=0,"",INDEX(Transaksi!$J$2:$J$2001,K14)),"")) | G14: =IF(J14="H",(SUMIFS(Transaksi!$G$2:$G$2001,Transaksi!$M$2:$M$2001,"<="&S14)+SUMIFS(Transaksi!$H$2:$H$2001,Transaksi!$M$2:$M$2001,"<="&S14)+SUMIFS(Transaksi!$I$2:$I$2001,Transaksi!$M$2:$M$2001,"<="&S14))-(SUMIFS(Transaksi!$J$2:$J$2001,Transaksi!$M$2:$M$2001,"<="&S14)),"") | I14: =IF(11>$O$2,"",MATCH(11,$Q$3:$Q$402,1)) | J14: =IF(I14="","",IF(11=INDEX($Q$3:$Q$402,I14),"H","E")) | K14: =IF(J14<>"E","",MATCH(S14,Transaksi!$M$2:$M$2001,0)+11-INDEX($Q$3:$Q$402,I14)-1) | N14: 12 | O14: =IF(N14<=$O$1,$O$1-N14+1,"") | P14: =IF(O14="",0,COUNTIF(Transaksi!$M$2:$M$2001,O14)+1) | Q14: =1+SUM(P$2:P13) | S14: =IF(I14="","",INDEX($O$3:$O$402,I14)) | T14: =IF(J14<>"H","",INDEX(Transaksi!$A$2:$A$2001,MATCH(S14,Transaksi!$M$2:$M$2001,0)))
A15: =IF(J15="E",IF(INDEX(Transaksi!$J$2:$J$2001,K15)>0,"↑","↓"),"") | B15: =IF(J15="H",CHOOSE(WEEKDAY(T15,2),"Isnin","Selasa","Rabu","Khamis","Jumaat","Sabtu","Ahad")&", "&DAY(T15)&" "&CHOOSE(MONTH(T15),"Jan","Feb","Mac","Apr","Mei","Jun","Jul","Ogo","Sep","Okt","Nov","Dis")&" "&YEAR(T15),IF(J15="E",IF(INDEX(Transaksi!$B$2:$B$2001,K15)="",INDEX(Transaksi!$C$2:$C$2001,K15)&" · "&INDEX(Transaksi!$D$2:$D$2001,K15),INDEX(Transaksi!$B$2:$B$2001,K15)),"")) | C15: =IF(J15="E",INDEX(Transaksi!$C$2:$C$2001,K15)&"","") | D15: =IF(J15="E",INDEX(Transaksi!$D$2:$D$2001,K15)&"","") | E15: =IF(J15="H",SUMIFS(Transaksi!$G$2:$G$2001,Transaksi!$M$2:$M$2001,"="&S15)+SUMIFS(Transaksi!$H$2:$H$2001,Transaksi!$M$2:$M$2001,"="&S15)+SUMIFS(Transaksi!$I$2:$I$2001,Transaksi!$M$2:$M$2001,"="&S15),IF(J15="E",IF(INDEX(Transaksi!$G$2:$G$2001,K15)+INDEX(Transaksi!$H$2:$H$2001,K15)+INDEX(Transaksi!$I$2:$I$2001,K15)=0,"",INDEX(Transaksi!$G$2:$G$2001,K15)+INDEX(Transaksi!$H$2:$H$2001,K15)+INDEX(Transaksi!$I$2:$I$2001,K15)),"")) | F15: =IF(J15="H",SUMIFS(Transaksi!$J$2:$J$2001,Transaksi!$M$2:$M$2001,"="&S15),IF(J15="E",IF(INDEX(Transaksi!$J$2:$J$2001,K15)=0,"",INDEX(Transaksi!$J$2:$J$2001,K15)),"")) | G15: =IF(J15="H",(SUMIFS(Transaksi!$G$2:$G$2001,Transaksi!$M$2:$M$2001,"<="&S15)+SUMIFS(Transaksi!$H$2:$H$2001,Transaksi!$M$2:$M$2001,"<="&S15)+SUMIFS(Transaksi!$I$2:$I$2001,Transaksi!$M$2:$M$2001,"<="&S15))-(SUMIFS(Transaksi!$J$2:$J$2001,Transaksi!$M$2:$M$2001,"<="&S15)),"") | I15: =IF(12>$O$2,"",MATCH(12,$Q$3:$Q$402,1)) | J15: =IF(I15="","",IF(12=INDEX($Q$3:$Q$402,I15),"H","E")) | K15: =IF(J15<>"E","",MATCH(S15,Transaksi!$M$2:$M$2001,0)+12-INDEX($Q$3:$Q$402,I15)-1) | N15: 13 | O15: =IF(N15<=$O$1,$O$1-N15+1,"") | P15: =IF(O15="",0,COUNTIF(Transaksi!$M$2:$M$2001,O15)+1) | Q15: =1+SUM(P$2:P14) | S15: =IF(I15="","",INDEX($O$3:$O$402,I15)) | T15: =IF(J15<>"H","",INDEX(Transaksi!$A$2:$A$2001,MATCH(S15,Transaksi!$M$2:$M$2001,0)))
A16: =IF(J16="E",IF(INDEX(Transaksi!$J$2:$J$2001,K16)>0,"↑","↓"),"") | B16: =IF(J16="H",CHOOSE(WEEKDAY(T16,2),"Isnin","Selasa","Rabu","Khamis","Jumaat","Sabtu","Ahad")&", "&DAY(T16)&" "&CHOOSE(MONTH(T16),"Jan","Feb","Mac","Apr","Mei","Jun","Jul","Ogo","Sep","Okt","Nov","Dis")&" "&YEAR(T16),IF(J16="E",IF(INDEX(Transaksi!$B$2:$B$2001,K16)="",INDEX(Transaksi!$C$2:$C$2001,K16)&" · "&INDEX(Transaksi!$D$2:$D$2001,K16),INDEX(Transaksi!$B$2:$B$2001,K16)),"")) | C16: =IF(J16="E",INDEX(Transaksi!$C$2:$C$2001,K16)&"","") | D16: =IF(J16="E",INDEX(Transaksi!$D$2:$D$2001,K16)&"","") | E16: =IF(J16="H",SUMIFS(Transaksi!$G$2:$G$2001,Transaksi!$M$2:$M$2001,"="&S16)+SUMIFS(Transaksi!$H$2:$H$2001,Transaksi!$M$2:$M$2001,"="&S16)+SUMIFS(Transaksi!$I$2:$I$2001,Transaksi!$M$2:$M$2001,"="&S16),IF(J16="E",IF(INDEX(Transaksi!$G$2:$G$2001,K16)+INDEX(Transaksi!$H$2:$H$2001,K16)+INDEX(Transaksi!$I$2:$I$2001,K16)=0,"",INDEX(Transaksi!$G$2:$G$2001,K16)+INDEX(Transaksi!$H$2:$H$2001,K16)+INDEX(Transaksi!$I$2:$I$2001,K16)),"")) | F16: =IF(J16="H",SUMIFS(Transaksi!$J$2:$J$2001,Transaksi!$M$2:$M$2001,"="&S16),IF(J16="E",IF(INDEX(Transaksi!$J$2:$J$2001,K16)=0,"",INDEX(Transaksi!$J$2:$J$2001,K16)),"")) | G16: =IF(J16="H",(SUMIFS(Transaksi!$G$2:$G$2001,Transaksi!$M$2:$M$2001,"<="&S16)+SUMIFS(Transaksi!$H$2:$H$2001,Transaksi!$M$2:$M$2001,"<="&S16)+SUMIFS(Transaksi!$I$2:$I$2001,Transaksi!$M$2:$M$2001,"<="&S16))-(SUMIFS(Transaksi!$J$2:$J$2001,Transaksi!$M$2:$M$2001,"<="&S16)),"") | I16: =IF(13>$O$2,"",MATCH(13,$Q$3:$Q$402,1)) | J16: =IF(I16="","",IF(13=INDEX($Q$3:$Q$402,I16),"H","E")) | K16: =IF(J16<>"E","",MATCH(S16,Transaksi!$M$2:$M$2001,0)+13-INDEX($Q$3:$Q$402,I16)-1) | N16: 14 | O16: =IF(N16<=$O$1,$O$1-N16+1,"") | P16: =IF(O16="",0,COUNTIF(Transaksi!$M$2:$M$2001,O16)+1) | Q16: =1+SUM(P$2:P15) | S16: =IF(I16="","",INDEX($O$3:$O$402,I16)) | T16: =IF(J16<>"H","",INDEX(Transaksi!$A$2:$A$2001,MATCH(S16,Transaksi!$M$2:$M$2001,0)))
A17: =IF(J17="E",IF(INDEX(Transaksi!$J$2:$J$2001,K17)>0,"↑","↓"),"") | B17: =IF(J17="H",CHOOSE(WEEKDAY(T17,2),"Isnin","Selasa","Rabu","Khamis","Jumaat","Sabtu","Ahad")&", "&DAY(T17)&" "&CHOOSE(MONTH(T17),"Jan","Feb","Mac","Apr","Mei","Jun","Jul","Ogo","Sep","Okt","Nov","Dis")&" "&YEAR(T17),IF(J17="E",IF(INDEX(Transaksi!$B$2:$B$2001,K17)="",INDEX(Transaksi!$C$2:$C$2001,K17)&" · "&INDEX(Transaksi!$D$2:$D$2001,K17),INDEX(Transaksi!$B$2:$B$2001,K17)),"")) | C17: =IF(J17="E",INDEX(Transaksi!$C$2:$C$2001,K17)&"","") | D17: =IF(J17="E",INDEX(Transaksi!$D$2:$D$2001,K17)&"","") | E17: =IF(J17="H",SUMIFS(Transaksi!$G$2:$G$2001,Transaksi!$M$2:$M$2001,"="&S17)+SUMIFS(Transaksi!$H$2:$H$2001,Transaksi!$M$2:$M$2001,"="&S17)+SUMIFS(Transaksi!$I$2:$I$2001,Transaksi!$M$2:$M$2001,"="&S17),IF(J17="E",IF(INDEX(Transaksi!$G$2:$G$2001,K17)+INDEX(Transaksi!$H$2:$H$2001,K17)+INDEX(Transaksi!$I$2:$I$2001,K17)=0,"",INDEX(Transaksi!$G$2:$G$2001,K17)+INDEX(Transaksi!$H$2:$H$2001,K17)+INDEX(Transaksi!$I$2:$I$2001,K17)),"")) | F17: =IF(J17="H",SUMIFS(Transaksi!$J$2:$J$2001,Transaksi!$M$2:$M$2001,"="&S17),IF(J17="E",IF(INDEX(Transaksi!$J$2:$J$2001,K17)=0,"",INDEX(Transaksi!$J$2:$J$2001,K17)),"")) | G17: =IF(J17="H",(SUMIFS(Transaksi!$G$2:$G$2001,Transaksi!$M$2:$M$2001,"<="&S17)+SUMIFS(Transaksi!$H$2:$H$2001,Transaksi!$M$2:$M$2001,"<="&S17)+SUMIFS(Transaksi!$I$2:$I$2001,Transaksi!$M$2:$M$2001,"<="&S17))-(SUMIFS(Transaksi!$J$2:$J$2001,Transaksi!$M$2:$M$2001,"<="&S17)),"") | I17: =IF(14>$O$2,"",MATCH(14,$Q$3:$Q$402,1)) | J17: =IF(I17="","",IF(14=INDEX($Q$3:$Q$402,I17),"H","E")) | K17: =IF(J17<>"E","",MATCH(S17,Transaksi!$M$2:$M$2001,0)+14-INDEX($Q$3:$Q$402,I17)-1) | N17: 15 | O17: =IF(N17<=$O$1,$O$1-N17+1,"") | P17: =IF(O17="",0,COUNTIF(Transaksi!$M$2:$M$2001,O17)+1) | Q17: =1+SUM(P$2:P16) | S17: =IF(I17="","",INDEX($O$3:$O$402,I17)) | T17: =IF(J17<>"H","",INDEX(Transaksi!$A$2:$A$2001,MATCH(S17,Transaksi!$M$2:$M$2001,0)))
A18: =IF(J18="E",IF(INDEX(Transaksi!$J$2:$J$2001,K18)>0,"↑","↓"),"") | B18: =IF(J18="H",CHOOSE(WEEKDAY(T18,2),"Isnin","Selasa","Rabu","Khamis","Jumaat","Sabtu","Ahad")&", "&DAY(T18)&" "&CHOOSE(MONTH(T18),"Jan","Feb","Mac","Apr","Mei","Jun","Jul","Ogo","Sep","Okt","Nov","Dis")&" "&YEAR(T18),IF(J18="E",IF(INDEX(Transaksi!$B$2:$B$2001,K18)="",INDEX(Transaksi!$C$2:$C$2001,K18)&" · "&INDEX(Transaksi!$D$2:$D$2001,K18),INDEX(Transaksi!$B$2:$B$2001,K18)),"")) | C18: =IF(J18="E",INDEX(Transaksi!$C$2:$C$2001,K18)&"","") | D18: =IF(J18="E",INDEX(Transaksi!$D$2:$D$2001,K18)&"","") | E18: =IF(J18="H",SUMIFS(Transaksi!$G$2:$G$2001,Transaksi!$M$2:$M$2001,"="&S18)+SUMIFS(Transaksi!$H$2:$H$2001,Transaksi!$M$2:$M$2001,"="&S18)+SUMIFS(Transaksi!$I$2:$I$2001,Transaksi!$M$2:$M$2001,"="&S18),IF(J18="E",IF(INDEX(Transaksi!$G$2:$G$2001,K18)+INDEX(Transaksi!$H$2:$H$2001,K18)+INDEX(Transaksi!$I$2:$I$2001,K18)=0,"",INDEX(Transaksi!$G$2:$G$2001,K18)+INDEX(Transaksi!$H$2:$H$2001,K18)+INDEX(Transaksi!$I$2:$I$2001,K18)),"")) | F18: =IF(J18="H",SUMIFS(Transaksi!$J$2:$J$2001,Transaksi!$M$2:$M$2001,"="&S18),IF(J18="E",IF(INDEX(Transaksi!$J$2:$J$2001,K18)=0,"",INDEX(Transaksi!$J$2:$J$2001,K18)),"")) | G18: =IF(J18="H",(SUMIFS(Transaksi!$G$2:$G$2001,Transaksi!$M$2:$M$2001,"<="&S18)+SUMIFS(Transaksi!$H$2:$H$2001,Transaksi!$M$2:$M$2001,"<="&S18)+SUMIFS(Transaksi!$I$2:$I$2001,Transaksi!$M$2:$M$2001,"<="&S18))-(SUMIFS(Transaksi!$J$2:$J$2001,Transaksi!$M$2:$M$2001,"<="&S18)),"") | I18: =IF(15>$O$2,"",MATCH(15,$Q$3:$Q$402,1)) | J18: =IF(I18="","",IF(15=INDEX($Q$3:$Q$402,I18),"H","E")) | K18: =IF(J18<>"E","",MATCH(S18,Transaksi!$M$2:$M$2001,0)+15-INDEX($Q$3:$Q$402,I18)-1) | N18: 16 | O18: =IF(N18<=$O$1,$O$1-N18+1,"") | P18: =IF(O18="",0,COUNTIF(Transaksi!$M$2:$M$2001,O18)+1) | Q18: =1+SUM(P$2:P17) | S18: =IF(I18="","",INDEX($O$3:$O$402,I18)) | T18: =IF(J18<>"H","",INDEX(Transaksi!$A$2:$A$2001,MATCH(S18,Transaksi!$M$2:$M$2001,0)))
A19: =IF(J19="E",IF(INDEX(Transaksi!$J$2:$J$2001,K19)>0,"↑","↓"),"") | B19: =IF(J19="H",CHOOSE(WEEKDAY(T19,2),"Isnin","Selasa","Rabu","Khamis","Jumaat","Sabtu","Ahad")&", "&DAY(T19)&" "&CHOOSE(MONTH(T19),"Jan","Feb","Mac","Apr","Mei","Jun","Jul","Ogo","Sep","Okt","Nov","Dis")&" "&YEAR(T19),IF(J19="E",IF(INDEX(Transaksi!$B$2:$B$2001,K19)="",INDEX(Transaksi!$C$2:$C$2001,K19)&" · "&INDEX(Transaksi!$D$2:$D$2001,K19),INDEX(Transaksi!$B$2:$B$2001,K19)),"")) | C19: =IF(J19="E",INDEX(Transaksi!$C$2:$C$2001,K19)&"","") | D19: =IF(J19="E",INDEX(Transaksi!$D$2:$D$2001,K19)&"","") | E19: =IF(J19="H",SUMIFS(Transaksi!$G$2:$G$2001,Transaksi!$M$2:$M$2001,"="&S19)+SUMIFS(Transaksi!$H$2:$H$2001,Transaksi!$M$2:$M$2001,"="&S19)+SUMIFS(Transaksi!$I$2:$I$2001,Transaksi!$M$2:$M$2001,"="&S19),IF(J19="E",IF(INDEX(Transaksi!$G$2:$G$2001,K19)+INDEX(Transaksi!$H$2:$H$2001,K19)+INDEX(Transaksi!$I$2:$I$2001,K19)=0,"",INDEX(Transaksi!$G$2:$G$2001,K19)+INDEX(Transaksi!$H$2:$H$2001,K19)+INDEX(Transaksi!$I$2:$I$2001,K19)),"")) | F19: =IF(J19="H",SUMIFS(Transaksi!$J$2:$J$2001,Transaksi!$M$2:$M$2001,"="&S19),IF(J19="E",IF(INDEX(Transaksi!$J$2:$J$2001,K19)=0,"",INDEX(Transaksi!$J$2:$J$2001,K19)),"")) | G19: =IF(J19="H",(SUMIFS(Transaksi!$G$2:$G$2001,Transaksi!$M$2:$M$2001,"<="&S19)+SUMIFS(Transaksi!$H$2:$H$2001,Transaksi!$M$2:$M$2001,"<="&S19)+SUMIFS(Transaksi!$I$2:$I$2001,Transaksi!$M$2:$M$2001,"<="&S19))-(SUMIFS(Transaksi!$J$2:$J$2001,Transaksi!$M$2:$M$2001,"<="&S19)),"") | I19: =IF(16>$O$2,"",MATCH(16,$Q$3:$Q$402,1)) | J19: =IF(I19="","",IF(16=INDEX($Q$3:$Q$402,I19),"H","E")) | K19: =IF(J19<>"E","",MATCH(S19,Transaksi!$M$2:$M$2001,0)+16-INDEX($Q$3:$Q$402,I19)-1) | N19: 17 | O19: =IF(N19<=$O$1,$O$1-N19+1,"") | P19: =IF(O19="",0,COUNTIF(Transaksi!$M$2:$M$2001,O19)+1) | Q19: =1+SUM(P$2:P18) | S19: =IF(I19="","",INDEX($O$3:$O$402,I19)) | T19: =IF(J19<>"H","",INDEX(Transaksi!$A$2:$A$2001,MATCH(S19,Transaksi!$M$2:$M$2001,0)))
A20: =IF(J20="E",IF(INDEX(Transaksi!$J$2:$J$2001,K20)>0,"↑","↓"),"") | B20: =IF(J20="H",CHOOSE(WEEKDAY(T20,2),"Isnin","Selasa","Rabu","Khamis","Jumaat","Sabtu","Ahad")&", "&DAY(T20)&" "&CHOOSE(MONTH(T20),"Jan","Feb","Mac","Apr","Mei","Jun","Jul","Ogo","Sep","Okt","Nov","Dis")&" "&YEAR(T20),IF(J20="E",IF(INDEX(Transaksi!$B$2:$B$2001,K20)="",INDEX(Transaksi!$C$2:$C$2001,K20)&" · "&INDEX(Transaksi!$D$2:$D$2001,K20),INDEX(Transaksi!$B$2:$B$2001,K20)),"")) | C20: =IF(J20="E",INDEX(Transaksi!$C$2:$C$2001,K20)&"","") | D20: =IF(J20="E",INDEX(Transaksi!$D$2:$D$2001,K20)&"","") | E20: =IF(J20="H",SUMIFS(Transaksi!$G$2:$G$2001,Transaksi!$M$2:$M$2001,"="&S20)+SUMIFS(Transaksi!$H$2:$H$2001,Transaksi!$M$2:$M$2001,"="&S20)+SUMIFS(Transaksi!$I$2:$I$2001,Transaksi!$M$2:$M$2001,"="&S20),IF(J20="E",IF(INDEX(Transaksi!$G$2:$G$2001,K20)+INDEX(Transaksi!$H$2:$H$2001,K20)+INDEX(Transaksi!$I$2:$I$2001,K20)=0,"",INDEX(Transaksi!$G$2:$G$2001,K20)+INDEX(Transaksi!$H$2:$H$2001,K20)+INDEX(Transaksi!$I$2:$I$2001,K20)),"")) | F20: =IF(J20="H",SUMIFS(Transaksi!$J$2:$J$2001,Transaksi!$M$2:$M$2001,"="&S20),IF(J20="E",IF(INDEX(Transaksi!$J$2:$J$2001,K20)=0,"",INDEX(Transaksi!$J$2:$J$2001,K20)),"")) | G20: =IF(J20="H",(SUMIFS(Transaksi!$G$2:$G$2001,Transaksi!$M$2:$M$2001,"<="&S20)+SUMIFS(Transaksi!$H$2:$H$2001,Transaksi!$M$2:$M$2001,"<="&S20)+SUMIFS(Transaksi!$I$2:$I$2001,Transaksi!$M$2:$M$2001,"<="&S20))-(SUMIFS(Transaksi!$J$2:$J$2001,Transaksi!$M$2:$M$2001,"<="&S20)),"") | I20: =IF(17>$O$2,"",MATCH(17,$Q$3:$Q$402,1)) | J20: =IF(I20="","",IF(17=INDEX($Q$3:$Q$402,I20),"H","E")) | K20: =IF(J20<>"E","",MATCH(S20,Transaksi!$M$2:$M$2001,0)+17-INDEX($Q$3:$Q$402,I20)-1) | N20: 18 | O20: =IF(N20<=$O$1,$O$1-N20+1,"") | P20: =IF(O20="",0,COUNTIF(Transaksi!$M$2:$M$2001,O20)+1) | Q20: =1+SUM(P$2:P19) | S20: =IF(I20="","",INDEX($O$3:$O$402,I20)) | T20: =IF(J20<>"H","",INDEX(Transaksi!$A$2:$A$2001,MATCH(S20,Transaksi!$M$2:$M$2001,0)))
A21: =IF(J21="E",IF(INDEX(Transaksi!$J$2:$J$2001,K21)>0,"↑","↓"),"") | B21: =IF(J21="H",CHOOSE(WEEKDAY(T21,2),"Isnin","Selasa","Rabu","Khamis","Jumaat","Sabtu","Ahad")&", "&DAY(T21)&" "&CHOOSE(MONTH(T21),"Jan","Feb","Mac","Apr","Mei","Jun","Jul","Ogo","Sep","Okt","Nov","Dis")&" "&YEAR(T21),IF(J21="E",IF(INDEX(Transaksi!$B$2:$B$2001,K21)="",INDEX(Transaksi!$C$2:$C$2001,K21)&" · "&INDEX(Transaksi!$D$2:$D$2001,K21),INDEX(Transaksi!$B$2:$B$2001,K21)),"")) | C21: =IF(J21="E",INDEX(Transaksi!$C$2:$C$2001,K21)&"","") | D21: =IF(J21="E",INDEX(Transaksi!$D$2:$D$2001,K21)&"","") | E21: =IF(J21="H",SUMIFS(Transaksi!$G$2:$G$2001,Transaksi!$M$2:$M$2001,"="&S21)+SUMIFS(Transaksi!$H$2:$H$2001,Transaksi!$M$2:$M$2001,"="&S21)+SUMIFS(Transaksi!$I$2:$I$2001,Transaksi!$M$2:$M$2001,"="&S21),IF(J21="E",IF(INDEX(Transaksi!$G$2:$G$2001,K21)+INDEX(Transaksi!$H$2:$H$2001,K21)+INDEX(Transaksi!$I$2:$I$2001,K21)=0,"",INDEX(Transaksi!$G$2:$G$2001,K21)+INDEX(Transaksi!$H$2:$H$2001,K21)+INDEX(Transaksi!$I$2:$I$2001,K21)),"")) | F21: =IF(J21="H",SUMIFS(Transaksi!$J$2:$J$2001,Transaksi!$M$2:$M$2001,"="&S21),IF(J21="E",IF(INDEX(Transaksi!$J$2:$J$2001,K21)=0,"",INDEX(Transaksi!$J$2:$J$2001,K21)),"")) | G21: =IF(J21="H",(SUMIFS(Transaksi!$G$2:$G$2001,Transaksi!$M$2:$M$2001,"<="&S21)+SUMIFS(Transaksi!$H$2:$H$2001,Transaksi!$M$2:$M$2001,"<="&S21)+SUMIFS(Transaksi!$I$2:$I$2001,Transaksi!$M$2:$M$2001,"<="&S21))-(SUMIFS(Transaksi!$J$2:$J$2001,Transaksi!$M$2:$M$2001,"<="&S21)),"") | I21: =IF(18>$O$2,"",MATCH(18,$Q$3:$Q$402,1)) | J21: =IF(I21="","",IF(18=INDEX($Q$3:$Q$402,I21),"H","E")) | K21: =IF(J21<>"E","",MATCH(S21,Transaksi!$M$2:$M$2001,0)+18-INDEX($Q$3:$Q$402,I21)-1) | N21: 19 | O21: =IF(N21<=$O$1,$O$1-N21+1,"") | P21: =IF(O21="",0,COUNTIF(Transaksi!$M$2:$M$2001,O21)+1) | Q21: =1+SUM(P$2:P20) | S21: =IF(I21="","",INDEX($O$3:$O$402,I21)) | T21: =IF(J21<>"H","",INDEX(Transaksi!$A$2:$A$2001,MATCH(S21,Transaksi!$M$2:$M$2001,0)))
A22: =IF(J22="E",IF(INDEX(Transaksi!$J$2:$J$2001,K22)>0,"↑","↓"),"") | B22: =IF(J22="H",CHOOSE(WEEKDAY(T22,2),"Isnin","Selasa","Rabu","Khamis","Jumaat","Sabtu","Ahad")&", "&DAY(T22)&" "&CHOOSE(MONTH(T22),"Jan","Feb","Mac","Apr","Mei","Jun","Jul","Ogo","Sep","Okt","Nov","Dis")&" "&YEAR(T22),IF(J22="E",IF(INDEX(Transaksi!$B$2:$B$2001,K22)="",INDEX(Transaksi!$C$2:$C$2001,K22)&" · "&INDEX(Transaksi!$D$2:$D$2001,K22),INDEX(Transaksi!$B$2:$B$2001,K22)),"")) | C22: =IF(J22="E",INDEX(Transaksi!$C$2:$C$2001,K22)&"","") | D22: =IF(J22="E",INDEX(Transaksi!$D$2:$D$2001,K22)&"","") | E22: =IF(J22="H",SUMIFS(Transaksi!$G$2:$G$2001,Transaksi!$M$2:$M$2001,"="&S22)+SUMIFS(Transaksi!$H$2:$H$2001,Transaksi!$M$2:$M$2001,"="&S22)+SUMIFS(Transaksi!$I$2:$I$2001,Transaksi!$M$2:$M$2001,"="&S22),IF(J22="E",IF(INDEX(Transaksi!$G$2:$G$2001,K22)+INDEX(Transaksi!$H$2:$H$2001,K22)+INDEX(Transaksi!$I$2:$I$2001,K22)=0,"",INDEX(Transaksi!$G$2:$G$2001,K22)+INDEX(Transaksi!$H$2:$H$2001,K22)+INDEX(Transaksi!$I$2:$I$2001,K22)),"")) | F22: =IF(J22="H",SUMIFS(Transaksi!$J$2:$J$2001,Transaksi!$M$2:$M$2001,"="&S22),IF(J22="E",IF(INDEX(Transaksi!$J$2:$J$2001,K22)=0,"",INDEX(Transaksi!$J$2:$J$2001,K22)),"")) | G22: =IF(J22="H",(SUMIFS(Transaksi!$G$2:$G$2001,Transaksi!$M$2:$M$2001,"<="&S22)+SUMIFS(Transaksi!$H$2:$H$2001,Transaksi!$M$2:$M$2001,"<="&S22)+SUMIFS(Transaksi!$I$2:$I$2001,Transaksi!$M$2:$M$2001,"<="&S22))-(SUMIFS(Transaksi!$J$2:$J$2001,Transaksi!$M$2:$M$2001,"<="&S22)),"") | I22: =IF(19>$O$2,"",MATCH(19,$Q$3:$Q$402,1)) | J22: =IF(I22="","",IF(19=INDEX($Q$3:$Q$402,I22),"H","E")) | K22: =IF(J22<>"E","",MATCH(S22,Transaksi!$M$2:$M$2001,0)+19-INDEX($Q$3:$Q$402,I22)-1) | N22: 20 | O22: =IF(N22<=$O$1,$O$1-N22+1,"") | P22: =IF(O22="",0,COUNTIF(Transaksi!$M$2:$M$2001,O22)+1) | Q22: =1+SUM(P$2:P21) | S22: =IF(I22="","",INDEX($O$3:$O$402,I22)) | T22: =IF(J22<>"H","",INDEX(Transaksi!$A$2:$A$2001,MATCH(S22,Transaksi!$M$2:$M$2001,0)))
A23: =IF(J23="E",IF(INDEX(Transaksi!$J$2:$J$2001,K23)>0,"↑","↓"),"") | B23: =IF(J23="H",CHOOSE(WEEKDAY(T23,2),"Isnin","Selasa","Rabu","Khamis","Jumaat","Sabtu","Ahad")&", "&DAY(T23)&" "&CHOOSE(MONTH(T23),"Jan","Feb","Mac","Apr","Mei","Jun","Jul","Ogo","Sep","Okt","Nov","Dis")&" "&YEAR(T23),IF(J23="E",IF(INDEX(Transaksi!$B$2:$B$2001,K23)="",INDEX(Transaksi!$C$2:$C$2001,K23)&" · "&INDEX(Transaksi!$D$2:$D$2001,K23),INDEX(Transaksi!$B$2:$B$2001,K23)),"")) | C23: =IF(J23="E",INDEX(Transaksi!$C$2:$C$2001,K23)&"","") | D23: =IF(J23="E",INDEX(Transaksi!$D$2:$D$2001,K23)&"","") | E23: =IF(J23="H",SUMIFS(Transaksi!$G$2:$G$2001,Transaksi!$M$2:$M$2001,"="&S23)+SUMIFS(Transaksi!$H$2:$H$2001,Transaksi!$M$2:$M$2001,"="&S23)+SUMIFS(Transaksi!$I$2:$I$2001,Transaksi!$M$2:$M$2001,"="&S23),IF(J23="E",IF(INDEX(Transaksi!$G$2:$G$2001,K23)+INDEX(Transaksi!$H$2:$H$2001,K23)+INDEX(Transaksi!$I$2:$I$2001,K23)=0,"",INDEX(Transaksi!$G$2:$G$2001,K23)+INDEX(Transaksi!$H$2:$H$2001,K23)+INDEX(Transaksi!$I$2:$I$2001,K23)),"")) | F23: =IF(J23="H",SUMIFS(Transaksi!$J$2:$J$2001,Transaksi!$M$2:$M$2001,"="&S23),IF(J23="E",IF(INDEX(Transaksi!$J$2:$J$2001,K23)=0,"",INDEX(Transaksi!$J$2:$J$2001,K23)),"")) | G23: =IF(J23="H",(SUMIFS(Transaksi!$G$2:$G$2001,Transaksi!$M$2:$M$2001,"<="&S23)+SUMIFS(Transaksi!$H$2:$H$2001,Transaksi!$M$2:$M$2001,"<="&S23)+SUMIFS(Transaksi!$I$2:$I$2001,Transaksi!$M$2:$M$2001,"<="&S23))-(SUMIFS(Transaksi!$J$2:$J$2001,Transaksi!$M$2:$M$2001,"<="&S23)),"") | I23: =IF(20>$O$2,"",MATCH(20,$Q$3:$Q$402,1)) | J23: =IF(I23="","",IF(20=INDEX($Q$3:$Q$402,I23),"H","E")) | K23: =IF(J23<>"E","",MATCH(S23,Transaksi!$M$2:$M$2001,0)+20-INDEX($Q$3:$Q$402,I23)-1) | N23: 21 | O23: =IF(N23<=$O$1,$O$1-N23+1,"") | P23: =IF(O23="",0,COUNTIF(Transaksi!$M$2:$M$2001,O23)+1) | Q23: =1+SUM(P$2:P22) | S23: =IF(I23="","",INDEX($O$3:$O$402,I23)) | T23: =IF(J23<>"H","",INDEX(Transaksi!$A$2:$A$2001,MATCH(S23,Transaksi!$M$2:$M$2001,0)))
